Workbook

Sheet Guía
A1: Casos de prueba (CP) — Guía del formato
A3: HOJAS
A4: Resumen | B4: Una fila por historia: CP diseñados, positivos, negativos, ejecutados, OK/NOK y si cumple el mínimo de la profe.
A5: E1-HU1 … E2-HU4 | B5: Una hoja por historia de usuario de los Sprints 1 y 2, con los casos escritos con datos reales de SAIYAGYM y los mensajes exactos que muestra el sistema.
A6: Formato en blanco | B6: Plantilla vacía para las historias de los siguientes sprints.
A7: TIPO DE PRUEBA
A8: Funcionales | B8: Prueban lo que el sistema debe hacer según cada historia y sus criterios de aceptación, sin mirar el código. Este formato es de ese tipo. Las pruebas unitarias las hace el desarrollador en el código, y las de aceptación las valida el cliente.
A9: CÓMO LEER UNA HOJA
A10: Generalidades | B10: Fecha, historia (HU), módulo, No. SP, iteración y tipo de prueba. Amarillo = para completar.
A11: Alcance | B11: Cuántos CP tiene cada criterio de aceptación (CA). Se cuenta solo, leyendo el ID_CP.
A12: ID_CP | B12: HE1_HU1_CA1_CP001 = Épica 1, historia 1, criterio de aceptación 1, caso 001.
A13: Campos / Valores | B13: Cada dato que se ingresa (o se hace) y el valor exacto que se usa. Los renglones del mismo CP están agrupados.
A14: Sentido (+/-) | B14: Positivo (+): el dato es válido y debe salir bien. Negativo (-): el dato es inválido o la situación no permite la acción y el sistema debe rechazarla.
A15: Resultado esperado | B15: «Entonces CAn» + lo que dice el criterio + el mensaje exacto de la pantalla.
A16: Observación | B16: Precondición (qué debe existir antes), cómo probarlo (pantalla, API o base de datos) y si el CP es adicional al criterio.
A17: Al ejecutar
A18: Pasos | B18: Elige OK o NOK en «Resultado real». Pon el enlace de la evidencia (captura o video) o describe el fallo. Si es NOK, elige el nivel del error (Baja, Media, Alta). Las estadísticas se actualizan solas.
A19: Orden de ejecución | B19: Algunos CP dependen de otros (ej. E2-HU2 usa las rutinas de E2-HU1). Se ejecutan en el orden E1-HU1 → E2-HU4; la columna Observación lo indica.
A20: Casos con preparación en la base de datos | B20: «Usuario no encontrado» (E1-HU2 y E1-HU4) y «Rutina no encontrada» (E2-HU3): se deja el registro abierto en pantalla, se borra de la base de datos con SQL y luego se pulsa Guardar o Inactivar. «Rutina no disponible» (E2-HU4) se prepara con un UPDATE. Los pasos están en los documentos Pasos_.
A21: PARA CONFIRMAR CON LA PROFESORA
A22: 1 | B22: ¿«No. SP» es número de sprint o puntos de la historia? Lo dejé libre.
A23: 2 | B23: El «=PU» junto al ID y el esquema de la derecha de la pizarra («X3CP», «Ex», «Rg») no se leían con certeza; no los apliqué.
A24: 3 | B24: La regla «mínimo 2 positivos y 1 negativo» la apliqué por historia (el Resumen la verifica). Si es por criterio de aceptación, hay que agregar CP en los criterios que son solo negativos (ej. «Usuario duplicado»).
A25: 4 | B25: Los CP con la etiqueta [CP adicional] en Observación van más allá del criterio (formato de correo, contraseña, límites, permisos, concurrencia, integridad). Los que dicen «regla pendiente» proponen un resultado esperado que debe confirmarse; no son requisitos oficiales.
A26: 5 | B26: Nivel del error: Baja / Media / Alta (en la pizarra se ve «Baja»). Si usan otra escala, se cambia en la lista de la columna.
A27: 6 | B27: Los 68 CP originales tienen resultado OK y evidencia en Google Docs (revisada el 27/10/2026; detalle en la hoja «Revisión QA»). Los 43 CP adicionales se ejecutaron el 27/10/2026 en una copia de pruebas del código del proyecto: 32 OK, 10 NOK y 1 PENDIENTE (HE2_HU4_CA1_CP004, solo se reproduce entre 19:00 y 23:59 hora de Colombia). En la columna Evidencia, cada CP adicional es un enlace al Word «Evidencias_<HU>_adicionales.docx» y nombra la sección del CP. Los 8 enlaces de Google Drive están listados en la hoja «Evidencias».
A28: 7 | B28: En el sistema, las historias E1-HU2 y E1-HU3 están numeradas al revés que en el documento de HU (en código: HU2 = consultar, HU3 = actualizar). Aquí se usó la numeración del documento de HU.
A30: ETIQUETAS EN «OBSERVACIÓN» (agregadas en la revisión del 27/10/2026)
A31: [Verifica CAn] | B31: El CP comprueba directamente lo que dice el criterio de aceptación n.
A32: [CP adicional] | B32: El CP nace del análisis de riesgos: límites, formatos, permisos, concurrencia, relaciones entre módulos. La observación explica qué riesgo previene.
A33: [CP adicional – regla pendiente] | B33: La regla de negocio no está definida en la HU. El resultado esperado es una propuesta razonable que debe confirmarse con la profesora o el cliente.
A34: Prioridad de riesgo propuesta | B34: Alta / Media / Baja según el daño que causaría el defecto si existiera. NO es el nivel del error: el nivel solo se asigna cuando el CP se ejecuta y da NOK.
A35: Nota de análisis | B35: Lo que sugiere la lectura del código fuente sobre el comportamiento probable. No es un resultado: el resultado real solo se registra al ejecutar con evidencia.
A37: NIVEL DEL ERROR (columna «Tipo / Nivel del error»; solo para CP con resultado NOK)
A38: Baja | B38: Defecto menor, impacto limitado y con alternativa sencilla. Ej.: texto de un mensaje con errores; información confusa que se corrige con «Limpiar».
A39: Media | B39: Afecta una funcionalidad importante, pero hay alternativa o el impacto está acotado. Ej.: se acepta un dato con formato inválido; error genérico en una operación que no corrompe datos.
A40: Alta | B40: Compromete una función crítica, la integridad de los datos, los permisos o la privacidad. Ej.: un rol sin permiso modifica datos; se crea un usuario duplicado; se ve la rutina de otra persona.
A41: Regla | B41: Un CP negativo con resultado OK NO es un defecto: el sistema rechazó bien la entrada inválida. Las estadísticas de errores cuentan solo CP NOK con nivel asignado.
A43: ESTADÍSTICAS
A44: Total CP diseñados | B44: Cuenta solo las celdas de ID_CP con el formato HEx_HUx_CAx_CPxxx (no cuenta títulos ni la fila separadora).
...

Sheet Resumen
A1: RESUMEN DE CASOS DE PRUEBA — SAIYAGYM · Sprint 1 y Sprint 2
A4: Historia | B4: Nombre | C4: Sprint | D4: CP diseñados | E4: Positivos (+) | F4: Negativos (-) | G4: Ejecutados | H4: OK | I4: NOK | J4: Pendientes | K4: ¿Cumple mínimo 2(+) y 1(-)?
A5: E1-HU1 | B5: Registrar usuarios | C5: Sprint 1 | D5: ='E1-HU1'!F5 -> 25 | E5: ='E1-HU1'!F12 -> 4 | F5: ='E1-HU1'!F13 -> 21 | G5: ='E1-HU1'!F6 -> 25 | H5: ='E1-HU1'!F7 -> 23 | I5: ='E1-HU1'!F8 -> 2 | J5: ='E1-HU1'!F11 -> 0 | K5: =IF(AND(E5>=2,F5>=1),"Sí cumple","NO cumple") -> Sí cumple
A6: E1-HU2 | B6: Actualizar información de usuarios | C6: Sprint 1 | D6: ='E1-HU2'!F5 -> 14 | E6: ='E1-HU2'!F12 -> 4 | F6: ='E1-HU2'!F13 -> 10 | G6: ='E1-HU2'!F6 -> 14 | H6: ='E1-HU2'!F7 -> 14 | I6: ='E1-HU2'!F8 -> 0 | J6: ='E1-HU2'!F11 -> 0 | K6: =IF(AND(E6>=2,F6>=1),"Sí cumple","NO cumple") -> Sí cumple
A7: E1-HU3 | B7: Consultar información de usuarios | C7: Sprint 1 | D7: ='E1-HU3'!F5 -> 12 | E7: ='E1-HU3'!F12 -> 4 | F7: ='E1-HU3'!F13 -> 8 | G7: ='E1-HU3'!F6 -> 12 | H7: ='E1-HU3'!F7 -> 11 | I7: ='E1-HU3'!F8 -> 1 | J7: ='E1-HU3'!F11 -> 0 | K7: =IF(AND(E7>=2,F7>=1),"Sí cumple","NO cumple") -> Sí cumple
A8: E1-HU4 | B8: Gestionar estado de usuarios | C8: Sprint 1 | D8: ='E1-HU4'!F5 -> 11 | E8: ='E1-HU4'!F12 -> 5 | F8: ='E1-HU4'!F13 -> 6 | G8: ='E1-HU4'!F6 -> 11 | H8: ='E1-HU4'!F7 -> 11 | I8: ='E1-HU4'!F8 -> 0 | J8: ='E1-HU4'!F11 -> 0 | K8: =IF(AND(E8>=2,F8>=1),"Sí cumple","NO cumple") -> Sí cumple
A9: E2-HU1 | B9: Crear rutina de entrenamiento | C9: Sprint 2 | D9: ='E2-HU1'!F5 -> 16 | E9: ='E2-HU1'!F12 -> 3 | F9: ='E2-HU1'!F13 -> 13 | G9: ='E2-HU1'!F6 -> 16 | H9: ='E2-HU1'!F7 -> 15 | I9: ='E2-HU1'!F8 -> 1 | J9: ='E2-HU1'!F11 -> 0 | K9: =IF(AND(E9>=2,F9>=1),"Sí cumple","NO cumple") -> Sí cumple
A10: E2-HU2 | B10: Asignar rutina a usuario | C10: Sprint 2 | D10: ='E2-HU2'!F5 -> 13 | E10: ='E2-HU2'!F12 -> 3 | F10: ='E2-HU2'!F13 -> 10 | G10: ='E2-HU2'!F6 -> 13 | H10: ='E2-HU2'!F7 -> 9 | I10: ='E2-HU2'!F8 -> 4 | J10: ='E2-HU2'!F11 -> 0 | K10: =IF(AND(E10>=2,F10>=1),"Sí cumple","NO cumple") -> Sí cumple
A11: E2-HU3 | B11: Modificar rutina de entrenamiento | C11: Sprint 2 | D11: ='E2-HU3'!F5 -> 11 | E11: ='E2-HU3'!F12 -> 4 | F11: ='E2-HU3'!F13 -> 7 | G11: ='E2-HU3'!F6 -> 11 | H11: ='E2-HU3'!F7 -> 10 | I11: ='E2-HU3'!F8 -> 1 | J11: ='E2-HU3'!F11 -> 0 | K11: =IF(AND(E11>=2,F11>=1),"Sí cumple","NO cumple") -> Sí cumple
A12: E2-HU4 | B12: Consultar rutina asignada | C12: Sprint 2 | D12: ='E2-HU4'!F5 -> 9 | E12: ='E2-HU4'!F12 -> 4 | F12: ='E2-HU4'!F13 -> 5 | G12: ='E2-HU4'!F6 -> 8 | H12: ='E2-HU4'!F7 -> 7 | I12: ='E2-HU4'!F8 -> 1 | J12: ='E2-HU4'!F11 -> 1 | K12: =IF(AND(E12>=2,F12>=1),"Sí cumple","NO cumple") -> Sí cumple
A13: TOTAL | D13: =SUM(D5:D12) -> 111 | E13: =SUM(E5:E12) -> 31 | F13: =SUM(F5:F12) -> 80 | G13: =SUM(G5:G12) -> 110 | H13: =SUM(H5:H12) -> 100 | I13: =SUM(I5:I12) -> 10 | J13: =SUM(J5:J12) -> 1 | K13: =COUNTIF(K5:K12,"Sí cumple")&" de 8 cumplen" -> 8 de 8 cumplen
A17: EJECUCIÓN, DEFECTOS Y CONTROL DE EVIDENCIAS POR HISTORIA
A18: Historia | B18: Nombre | C18: % de ejecución (ejecutados / diseñados) | D18: % OK (sobre ejecutados) | E18: % NOK (sobre ejecutados) | F18: Defectos Baja | G18: Defectos Media | H18: Defectos Alta | I18: NOK sin nivel asignado | J18: CP adicionales (riesgo) | K18: Ejecutados sin evidencia | L18: Control: (+) + (−) = diseñados
A19: =A5 -> E1-HU1 | B19: =B5 -> Registrar usuarios | C19: =IF(D5=0,"Sin CP",G5/D5) -> 1 | D19: =IF(G5=0,"Sin ejecutados",H5/G5) -> 0.92 | E19: =IF(G5=0,"Sin ejecutados",I5/G5) -> 0.08 | F19: ='E1-HU1'!F14 -> 1 | G19: ='E1-HU1'!F15 -> 1 | H19: ='E1-HU1'!F16 -> 0 | I19: =I5-SUM(F19:H19) -> 0 | J19: =SUMPRODUCT(--(LEFT('E1-HU1'!I19:I163,13)="[CP adicional")) -> 12 | K19: =COUNTIFS('E1-HU1'!F19:F163,"OK",'E1-HU1'!G19:G163,"")+COUNTIFS('E1-HU1'!F19:F163,"NOK",'E1-HU1'!G19:G163,"") -> 0 | L19: =IF(E5+F5=D5,"Coincide","Revisar") -> Coincide
A20: =A6 -> E1-HU2 | B20: =B6 -> Actualizar información de usuarios | C20: =IF(D6=0,"Sin CP",G6/D6) -> 1 | D20: =IF(G6=0,"Sin ejecutados",H6/G6) -> 1 | E20: =IF(G6=0,"Sin ejecutados",I6/G6) -> 0 | F20: ='E1-HU2'!F14 -> 0 | G20: ='E1-HU2'!F15 -> 0 | H20: ='E1-HU2'!F16 -> 0 | I20: =I6-SUM(F20:H20) -> 0 | J20: =SUMPRODUCT(--(LEFT('E1-HU2'!I19:I89,13)="[CP adicional")) -> 7 | K20: =COUNTIFS('E1-HU2'!F19:F89,"OK",'E1-HU2'!G19:G89,"")+COUNTIFS('E1-HU2'!F19:F89,"NOK",'E1-HU2'!G19:G89,"") -> 0 | L20: =IF(E6+F6=D6,"Coincide","Revisar") -> Coincide
A21: =A7 -> E1-HU3 | B21: =B7 -> Consultar información de usuarios | C21: =IF(D7=0,"Sin CP",G7/D7) -> 1 | D21: =IF(G7=0,"Sin ejecutados",H7/G7) -> 0.91666667 | E21: =IF(G7=0,"Sin ejecutados",I7/G7) -> 0.083333333 | F21: ='E1-HU3'!F14 -> 1 | G21: ='E1-HU3'!F15 -> 0 | H21: ='E1-HU3'!F16 -> 0 | I21: =I7-SUM(F21:H21) -> 0 | J21: =SUMPRODUCT(--(LEFT('E1-HU3'!I19:I44,13)="[CP adicional")) -> 5 | K21: =COUNTIFS('E1-HU3'!F19:F44,"OK",'E1-HU3'!G19:G44,"")+COUNTIFS('E1-HU3'!F19:F44,"NOK",'E1-HU3'!G19:G44,"") -> 0 | L21: =IF(E7+F7=D7,"Coincide","Revisar") -> Coincide
A22: =A8 -> E1-HU4 | B22: =B8 -> Gestionar estado de usuarios | C22: =IF(D8=0,"Sin CP",G8/D8) -> 1 | D22: =IF(G8=0,"Sin ejecutados",H8/G8) -> 1 | E22: =IF(G8=0,"Sin ejecutados",I8/G8) -> 0 | F22: ='E1-HU4'!F14 -> 0 | G22: ='E1-HU4'!F15 -> 0 | H22: ='E1-HU4'!F16 -> 0 | I22: =I8-SUM(F22:H22) -> 0 | J22: =SUMPRODUCT(--(LEFT('E1-HU4'!I19:I52,13)="[CP adicional")) -> 6 | K22: =COUNTIFS('E1-HU4'!F19:F52,"OK",'E1-HU4'!G19:G52,"")+COUNTIFS('E1-HU4'!F19:F52,"NOK",'E1-HU4'!G19:G52,"") -> 0 | L22: =IF(E8+F8=D8,"Coincide","Revisar") -> Coincide
A23: =A9 -> E2-HU1 | B23: =B9 -> Crear rutina de entrenamiento | C23: =IF(D9=0,"Sin CP",G9/D9) -> 1 | D23: =IF(G9=0,"Sin ejecutados",H9/G9) -> 0.9375 | E23: =IF(G9=0,"Sin ejecutados",I9/G9) -> 0.0625 | F23: ='E2-HU1'!F14 -> 0 | G23: ='E2-HU1'!F15 -> 1 | H23: ='E2-HU1'!F16 -> 0 | I23: =I9-SUM(F23:H23) -> 0 | J23: =SUMPRODUCT(--(LEFT('E2-HU1'!I19:I66,13)="[CP adicional")) -> 8 | K23: =COUNTIFS('E2-HU1'!F19:F66,"OK",'E2-HU1'!G19:G66,"")+COUNTIFS('E2-HU1'!F19:F66,"NOK",'E2-HU1'!G19:G66,"") -> 0 | L23: =IF(E9+F9=D9,"Coincide","Revisar") -> Coincide
A24: =A10 -> E2-HU2 | B24: =B10 -> Asignar rutina a usuario | C24: =IF(D10=0,"Sin CP",G10/D10) -> 1 | D24: =IF(G10=0,"Sin ejecutados",H10/G10) -> 0.69230769 | E24: =IF(G10=0,"Sin ejecutados",I10/G10) -> 0.30769231 | F24: ='E2-HU2'!F14 -> 3 | G24: ='E2-HU2'!F15 -> 1 | H24: ='E2-HU2'!F16 -> 0 | I24: =I10-SUM(F24:H24) -> 0 | J24: =SUMPRODUCT(--(LEFT('E2-HU2'!I19:I60,13)="[CP adicional")) -> 7 | K24: =COUNTIFS('E2-HU2'!F19:F60,"OK",'E2-HU2'!G19:G60,"")+COUNTIFS('E2-HU2'!F19:F60,"NOK",'E2-HU2'!G19:G60,"") -> 0 | L24: =IF(E10+F10=D10,"Coincide","Revisar") -> Coincide
A25: =A11 -> E2-HU3 | B25: =B11 -> Modificar rutina de entrenamiento | C25: =IF(D11=0,"Sin CP",G11/D11) -> 1 | D25: =IF(G11=0,"Sin ejecutados",H11/G11) -> 0.90909091 | E25: =IF(G11=0,"Sin ejecutados",I11/G11) -> 0.090909091 | F25: ='E2-HU3'!F14 -> 0 | G25: ='E2-HU3'!F15 -> 1 | H25: ='E2-HU3'!F16 -> 0 | I25: =I11-SUM(F25:H25) -> 0 | J25: =SUMPRODUCT(--(LEFT('E2-HU3'!I19:I56,13)="[CP adicional")) -> 4 | K25: =COUNTIFS('E2-HU3'!F19:F56,"OK",'E2-HU3'!G19:G56,"")+COUNTIFS('E2-HU3'!F19:F56,"NOK",'E2-HU3'!G19:G56,"") -> 0 | L25: =IF(E11+F11=D11,"Coincide","Revisar") -> Coincide
A26: =A12 -> E2-HU4 | B26: =B12 -> Consultar rutina asignada | C26: =IF(D12=0,"Sin CP",G12/D12) -> 0.88888889 | D26: =IF(G12=0,"Sin ejecutados",H12/G12) -> 0.875 | E26: =IF(G12=0,"Sin ejecutados",I12/G12) -> 0.125 | F26: ='E2-HU4'!F14 -> 1 | G26: ='E2-HU4'!F15 -> 0 | H26: ='E2-HU4'!F16 -> 0 | I26: =I12-SUM(F26:H26) -> 0 | J26: =SUMPRODUCT(--(LEFT('E2-HU4'!I19:I51,13)="[CP adicional")) -> 3 | K26: =COUNTIFS('E2-HU4'!F19:F51,"OK",'E2-HU4'!G19:G51,"")+COUNTIFS('E2-HU4'!F19:F51,"NOK",'E2-HU4'!G19:G51,"") -> 0 | L26: =IF(E12+F12=D12,"Coincide","Revisar") -> Coincide
A27: TOTAL | C27: =IF(D13=0,"Sin CP",G13/D13) -> 0.99099099 | D27: =IF(G13=0,"Sin ejecutados",H13/G13) -> 0.90909091 | E27: =IF(G13=0,"Sin ejecutados",I13/G13) -> 0.090909091 | F27: =SUM(F19:F26) -> 6 | G27: =SUM(G19:G26) -> 4 | H27: =SUM(H19:H26) -> 0 | I27: =SUM(I19:I26) -> 0 | J27: =SUM(J19:J26) -> 52 | K27: =SUM(K19:K26) -> 0 | L27: =IF(E13+F13=D13,"Coincide","Revisar") -> Coincide
A29: INDICADORES GLOBALES (qué mide cada uno y cuál es su denominador)
A30: Indicador | C30: Valor | D30: Qué mide · denominador · cálculo
A31: CP diseñados | C31: =D13 -> 111 | D31: Casos escritos en las 8 hojas (originales + adicionales). Suma de «Total CP diseñados» de cada hoja, que cuenta solo IDs con formato HEx_HUx_CAx_CPxxx.
A32: CP adicionales por análisis de riesgos | C32: =J27 -> 52 | D32: CP cuya observación empieza con [CP adicional]: van más allá del criterio de aceptación. Los originales que ya eran adicionales también se cuentan.
A33: CP ejecutados | C33: =G13 -> 110 | D33: CP con resultado real OK o NOK.
A34: CP pendientes de ejecución | C34: =J13 -> 1 | D34: Diseñados − ejecutados. Un CP pendiente no tiene resultado real ni nivel de error.
A35: % de ejecución | C35: =C27 -> 0.99099099 | D35: Ejecutados / diseñados. Mide avance de la ejecución, no calidad del software.
A36: % OK sobre ejecutados | C36: =D27 -> 0.90909091 | D36: OK / ejecutados. Proporción de CP ejecutados cuyo resultado real coincidió con el esperado. NO es el % de requisitos cumplidos ni la tasa de defectos: un CP negativo con OK significa que el sistema rechazó bien un dato inválido.
A37: % NOK sobre ejecutados | C37: =E27 -> 0.090909091 | D37: NOK / ejecutados. Proporción de CP ejecutados que encontraron un comportamiento distinto al esperado.
A38: Defectos confirmados (CP NOK) | C38: =I13 -> 10 | D38: Cantidad de CP con resultado NOK. Cada NOK debe tener descripción del fallo, evidencia y nivel.
A39: Defectos de nivel Alta / Media / Baja | C39: =H27&" / "&G27&" / "&F27 -> 0 / 4 / 6 | D39: CP NOK clasificados por severidad (columna «Tipo / Nivel del error»). La severidad depende del impacto del defecto observado, no de que el CP sea negativo.
A40: CP NOK sin nivel asignado | C40: =I27 -> 0 | D40: Control de calidad del registro: debe ser 0.
A41: CP ejecutados sin evidencia | C41: =K27 -> 0 | D41: Control: CP con OK o NOK cuya celda de evidencia está vacía. Debe ser 0.
A42: Historias que cumplen el mínimo | C42: =K13 -> 8 de 8 cumplen | D42: Historias con al menos 2 CP positivos y 1 negativo (regla de la profesora, aplicada por historia).
A44: Sin CP ejecutados, los porcentajes muestran «Sin ejecutados» en lugar de 0 % para no inducir a error. Si el libro se abre en Excel y algún valor no se actualiza, presionar Ctrl+Alt+F9 (recalcular todo).

Sheet E1-HU1
A1: DISEÑO DE CASOS DE PRUEBA (CP) — SAIYAGYM · E1-HU1 Registrar usuarios
A2: Rol que ejecuta: Administrador. Celdas amarillas = para completar al ejecutar. Alcance y estadísticas se calculan solos.
A4: GENERALIDADES DE LA PRUEBA | E4: ESTADÍSTICAS
A5: Fecha | B5: 2026-10-20 | E5: Total CP diseñados | F5: =COUNTIF(A19:A163,"HE?_HU?_CA?_CP???") -> 25
A6: HU | B6: E1-HU1 — Registrar usuarios | E6: Total CP ejecutados (OK + NOK) | F6: =COUNTIF(F19:F163,"OK")+COUNTIF(F19:F163,"NOK") -> 25
A7: Módulo | B7: Gestión de usuarios (Sprint 1) | E7: CP con resultado OK | F7: =COUNTIF(F19:F163,"OK") -> 23
A8: No. SP | E8: CP con resultado NOK | F8: =COUNTIF(F19:F163,"NOK") -> 2
A9: Iteración | E9: % OK sobre ejecutados | F9: =IF(F6=0,"Sin ejecutados",F7/F6) -> 0.92
A10: Tipo de prueba | B10: Funcional | E10: % NOK sobre ejecutados | F10: =IF(F6=0,"Sin ejecutados",F8/F6) -> 0.08
A11: Alcance (CP por criterio de aceptación) | E11: CP pendientes de ejecutar | F11: =F5-F6 -> 0
A12: CA1 · Registro exitoso | B12: =COUNTIF(A19:A163,"*_CA1_*") -> 7 | E12: CP positivos (+) | F12: =COUNTIF(D19:D163,"Positivo*") -> 4
A13: CA2 · Campos obligatorios incompletos | B13: =COUNTIF(A19:A163,"*_CA2_*") -> 13 | E13: CP negativos (-) | F13: =COUNTIF(D19:D163,"Negativo*") -> 21
A14: CA3 · Usuario duplicado | B14: =COUNTIF(A19:A163,"*_CA3_*") -> 5 | E14: Errores de nivel Baja (solo CP NOK) | F14: =COUNTIFS(F19:F163,"NOK",H19:H163,"*Baja") -> 1
A15: CA4 | B15: =COUNTIF(A19:A163,"*_CA4_*") -> 0 | E15: Errores de nivel Media (solo CP NOK) | F15: =COUNTIFS(F19:F163,"NOK",H19:H163,"*Media") -> 1
A16: Total CP | B16: =SUM(B12:B15) -> 25 | E16: Errores de nivel Alta (solo CP NOK) | F16: =COUNTIFS(F19:F163,"NOK",H19:H163,"*Alta") -> 0
A17: DETALLE (CP)
A18: ID_CP | B18: Campos | C18: Valores | D18: Sentido (+/-) | E18: Resultado esperado | F18: Resultado real (OK / NOK) | G18: Evidencia (enlace) o descripción del fallo | H18: Tipo / Nivel del error | I18: Observación
A19: HE1_HU1_CA1_CP001 | B19: Nombre completo | C19: Pedro Ruiz | D19: Positivo (+) | E19: Entonces CA1: el sistema crea el usuario y muestra «Usuario registrado correctamente.» | F19: OK | G19: https://docs.google.com/document/d/1QQVp4MpEKhB28qrx3a3Iag5cRzZDnUSb/edit?usp=drive_link&ouid=103533695958335943637&rtpof=true&sd=true | I19: [Verifica CA1] Precondición: sesión de administrador, pantalla Usuarios. Caso base. Queda registrado el documento 55550001 (lo usan otros CP). Evidencia verificada (27/10/2026): el documento tiene una sección para este CP con 2 capturas que muestran los datos ingresados y el resultado esperado. El contador pasa de 5 a 6 usuarios.
B20: Número de documento | C20: 55550001
B21: Teléfono | C21: 3101234567
B22: Correo electrónico | C22: pedro@mail.com
B23: Rol | C23: usuario
B24: Contraseña | C24: Clave12345
A25: HE1_HU1_CA1_CP002 | B25: Nombre completo | C25: Laura Mora | D25: Positivo (+) | E25: Entonces CA1: el sistema crea el usuario y muestra «Entrenador registrado correctamente.» (mensaje según el rol, verificado en la evidencia). | F25: OK | G25: https://docs.google.com/document/d/1QQVp4MpEKhB28qrx3a3Iag5cRzZDnUSb/edit?usp=drive_link&ouid=103533695958335943637&rtpof=true&sd=true | I25: [Verifica CA1] Precondición: sesión de administrador, pantalla Usuarios. Rol entrenador y teléfono con indicativo. Evidencia verificada (27/10/2026): la captura muestra «Entrenador registrado correctamente.» y el contador pasa de 6 a 7. Corrección: el resultado esperado decía «Usuario registrado correctamente.»; se ajustó al mensaje real del sistema, que depende del rol. Si el CA exige el texto exacto «Usuario registrado correctamente.», este CP sería NOK (Baja). Confirmar con la profesora.
B26: Número de documento | C26: 55550002
B27: Teléfono | C27: +57 310 555 0002
B28: Correo electrónico | C28: laura@mail.com
B29: Rol | C29: entrenador
B30: Contraseña | C30: Entren2026
A31: HE1_HU1_CA1_CP003 | B31: Nombre completo | C31: Ana Torres | D31: Positivo (+) | E31: Entonces CA1: el sistema crea el usuario y muestra «Administrador registrado correctamente.» (mensaje según el rol, verificado en la evidencia). | F31: OK | G31: https://docs.google.com/document/d/1QQVp4MpEKhB28qrx3a3Iag5cRzZDnUSb/edit?usp=drive_link&ouid=103533695958335943637&rtpof=true&sd=true | I31: [Verifica CA1] Precondición: sesión de administrador, pantalla Usuarios. Rol administrador y documento con letras. Evidencia verificada (27/10/2026): la captura muestra «Administrador registrado correctamente.» y el contador pasa de 7 a 8. Misma corrección y misma confirmación pendiente que CA1_CP002.
B32: Número de documento | C32: AB1234
B33: Teléfono | C33: 3205550003
B34: Correo electrónico | C34: ana.torres@mail.com
B35: Rol | C35: administrador
B36: Contraseña | C36: Admin2026
A37: HE1_HU1_CA1_CP004 | B37: Nombre completo | C37: Luis Gómez | D37: Positivo (+) | E37: Entonces CA1: el sistema crea el usuario y muestra «Usuario registrado correctamente.» | F37: OK | G37: https://docs.google.com/document/d/1QQVp4MpEKhB28qrx3a3Iag5cRzZDnUSb/edit?usp=drive_link&ouid=103533695958335943637&rtpof=true&sd=true | I37: [Verifica CA1] Precondición: sesión de administrador, pantalla Usuarios. Valores límite: documento de 4 caracteres y contraseña de 8. Queda guardado como A123 (rol usuario, sin rutina: sirve para E2-HU4). Evidencia verificada (27/10/2026): el documento tiene una sección para este CP con 2 capturas que muestran los datos ingresados y el resultado esperado. El contador queda en 8 usuarios.
B38: Número de documento | C38: A123
B39: Teléfono | C39: 3005550004
B40: Correo electrónico | C40: luis@mail.com
B41: Rol | C41: usuario
...

Sheet E1-HU2
A1: DISEÑO DE CASOS DE PRUEBA (CP) — SAIYAGYM · E1-HU2 Actualizar información de usuarios
A2: Rol que ejecuta: Administrador. Celdas amarillas = para completar al ejecutar. Alcance y estadísticas se calculan solos.
A4: GENERALIDADES DE LA PRUEBA | E4: ESTADÍSTICAS
A5: Fecha | B5: 2026-10-20 | E5: Total CP diseñados | F5: =COUNTIF(A19:A89,"HE?_HU?_CA?_CP???") -> 14
A6: HU | B6: E1-HU2 — Actualizar información de usuarios | E6: Total CP ejecutados (OK + NOK) | F6: =COUNTIF(F19:F89,"OK")+COUNTIF(F19:F89,"NOK") -> 14
A7: Módulo | B7: Gestión de usuarios (Sprint 1) | E7: CP con resultado OK | F7: =COUNTIF(F19:F89,"OK") -> 14
A8: No. SP | E8: CP con resultado NOK | F8: =COUNTIF(F19:F89,"NOK") -> 0
A9: Iteración | E9: % OK sobre ejecutados | F9: =IF(F6=0,"Sin ejecutados",F7/F6) -> 1
A10: Tipo de prueba | B10: Funcional | E10: % NOK sobre ejecutados | F10: =IF(F6=0,"Sin ejecutados",F8/F6) -> 0
A11: Alcance (CP por criterio de aceptación) | E11: CP pendientes de ejecutar | F11: =F5-F6 -> 0
A12: CA1 · Actualización exitosa | B12: =COUNTIF(A19:A89,"*_CA1_*") -> 4 | E12: CP positivos (+) | F12: =COUNTIF(D19:D89,"Positivo*") -> 4
A13: CA2 · Usuario no encontrado | B13: =COUNTIF(A19:A89,"*_CA2_*") -> 2 | E13: CP negativos (-) | F13: =COUNTIF(D19:D89,"Negativo*") -> 10
A14: CA3 · Datos incompletos | B14: =COUNTIF(A19:A89,"*_CA3_*") -> 8 | E14: Errores de nivel Baja (solo CP NOK) | F14: =COUNTIFS(F19:F89,"NOK",H19:H89,"*Baja") -> 0
A15: CA4 | B15: =COUNTIF(A19:A89,"*_CA4_*") -> 0 | E15: Errores de nivel Media (solo CP NOK) | F15: =COUNTIFS(F19:F89,"NOK",H19:H89,"*Media") -> 0
A16: Total CP | B16: =SUM(B12:B15) -> 14 | E16: Errores de nivel Alta (solo CP NOK) | F16: =COUNTIFS(F19:F89,"NOK",H19:H89,"*Alta") -> 0
A17: DETALLE (CP)
A18: ID_CP | B18: Campos | C18: Valores | D18: Sentido (+/-) | E18: Resultado esperado | F18: Resultado real (OK / NOK) | G18: Evidencia (enlace) o descripción del fallo | H18: Tipo / Nivel del error | I18: Observación
A19: HE1_HU2_CA1_CP001 | B19: Nombre completo | C19: Pedro Ruiz | D19: Positivo (+) | E19: Entonces CA1: el sistema guarda los cambios y muestra «Usuario actualizado correctamente.» | F19: OK | G19: https://docs.google.com/document/d/1qH6x9oWqjPh-aAiX5MJjBOjreEm26viX/edit?usp=drive_link&ouid=103533695958335943637&rtpof=true&sd=true | I19: [Verifica CA1] Precondición: sesión de administrador; clic en «Editar» del usuario. Usuario: Pedro Ruiz (E1-HU1 CA1_CP001). Solo cambia el teléfono; la lista debe mostrar el nuevo valor. Evidencia verificada (27/10/2026): el documento tiene una sección para este CP con 2 capturas que muestran los datos ingresados y el resultado esperado. La captura del resultado muestra el mensaje, pero no la fila con el nuevo teléfono; el valor 3109998877 sí se ve en la evidencia de E1-HU4.
B20: Número de documento | C20: 55550001
B21: Teléfono | C21: 3109998877
B22: Correo electrónico | C22: pedro@mail.com
B23: Rol | C23: usuario
B24: Contraseña | C24: (vacío = conserva la actual)
A25: HE1_HU2_CA1_CP002 | B25: Nombre completo | C25: Laura Mora Díaz | D25: Positivo (+) | E25: Entonces CA1: el sistema guarda los cambios y muestra «Usuario actualizado correctamente.» | F25: OK | G25: https://docs.google.com/document/d/1qH6x9oWqjPh-aAiX5MJjBOjreEm26viX/edit?usp=drive_link&ouid=103533695958335943637&rtpof=true&sd=true | I25: [Verifica CA1] Precondición: sesión de administrador; clic en «Editar» del usuario. Usuario: Laura Mora (E1-HU1 CA1_CP002). Cambia nombre y correo. Evidencia verificada (27/10/2026): el documento tiene una sección para este CP con 2 capturas que muestran los datos ingresados y el resultado esperado. La captura del resultado muestra el mensaje; el nombre y el correo nuevos se ven en la evidencia de E1-HU4.
B26: Número de documento | C26: 55550002
B27: Teléfono | C27: +57 310 555 0002
B28: Correo electrónico | C28: laura.mora@mail.com
B29: Rol | C29: entrenador
B30: Contraseña | C30: (vacío = conserva la actual)
A31: HE1_HU2_CA1_CP003 | B31: Nombre completo | C31: Pedro Ruiz | D31: Positivo (+) | E31: Entonces CA1: el sistema guarda los cambios y muestra «Usuario actualizado correctamente.» | F31: OK | G31: https://docs.google.com/document/d/1qH6x9oWqjPh-aAiX5MJjBOjreEm26viX/edit?usp=drive_link&ouid=103533695958335943637&rtpof=true&sd=true | I31: [Verifica CA1] Precondición: sesión de administrador; clic en «Editar» del usuario. Cambio de contraseña: después Pedro debe poder iniciar sesión con Nueva2026. Evidencia verificada (27/10/2026): el documento tiene una sección para este CP con 2 capturas que muestran los datos ingresados y el resultado esperado. Falta evidencia del inicio de sesión con Nueva2026 (solo se ve en E2-HU4, cuyo documento no es accesible). Agregar una captura del login de Pedro.
B32: Número de documento | C32: 55550001
B33: Teléfono | C33: 3109998877
B34: Correo electrónico | C34: pedro@mail.com
B35: Rol | C35: usuario
B36: Contraseña | C36: Nueva2026
A37: HE1_HU2_CA2_CP001 | B37: Nombre completo | C37: Temporal Prueba | D37: Negativo (-) | E37: Entonces CA2: el sistema rechaza los cambios y muestra «El usuario no existe.»; el formulario se limpia y la lista se actualiza. | F37: OK | G37: https://docs.google.com/document/d/1qH6x9oWqjPh-aAiX5MJjBOjreEm26viX/edit?usp=drive_link&ouid=103533695958335943637&rtpof=true&sd=true | I37: [Verifica CA2] Precondición: sesión de administrador; clic en «Editar» del usuario. Usuario temporal 55559999: se registra, se pulsa «Editar» y, sin cerrar el formulario, se borra de la base de datos con SQL. Luego se cambia el teléfono y se pulsa «Guardar cambios» (pasos en el documento Pasos_E1-HU2). Evidencia verificada (27/10/2026): el documento tiene una sección para este CP con 2 capturas que muestran los datos ingresados y el resultado esperado.
B38: Número de documento | C38: 55559999
B39: Teléfono | C39: 3109998877
B40: Correo electrónico | C40: temporal@mail.com
B41: Rol | C41: usuario
...

Sheet E1-HU3
A1: DISEÑO DE CASOS DE PRUEBA (CP) — SAIYAGYM · E1-HU3 Consultar información de usuarios
A2: Rol que ejecuta: Administrador. Celdas amarillas = para completar al ejecutar. Alcance y estadísticas se calculan solos.
A4: GENERALIDADES DE LA PRUEBA | E4: ESTADÍSTICAS
A5: Fecha | B5: 2026-10-20 | E5: Total CP diseñados | F5: =COUNTIF(A19:A44,"HE?_HU?_CA?_CP???") -> 12
A6: HU | B6: E1-HU3 — Consultar información de usuarios | E6: Total CP ejecutados (OK + NOK) | F6: =COUNTIF(F19:F44,"OK")+COUNTIF(F19:F44,"NOK") -> 12
A7: Módulo | B7: Gestión de usuarios (Sprint 1) | E7: CP con resultado OK | F7: =COUNTIF(F19:F44,"OK") -> 11
A8: No. SP | E8: CP con resultado NOK | F8: =COUNTIF(F19:F44,"NOK") -> 1
A9: Iteración | E9: % OK sobre ejecutados | F9: =IF(F6=0,"Sin ejecutados",F7/F6) -> 0.91666667
A10: Tipo de prueba | B10: Funcional | E10: % NOK sobre ejecutados | F10: =IF(F6=0,"Sin ejecutados",F8/F6) -> 0.083333333
A11: Alcance (CP por criterio de aceptación) | E11: CP pendientes de ejecutar | F11: =F5-F6 -> 0
A12: CA1 · Usuario encontrado | B12: =COUNTIF(A19:A44,"*_CA1_*") -> 5 | E12: CP positivos (+) | F12: =COUNTIF(D19:D44,"Positivo*") -> 4
A13: CA2 · Usuario no encontrado | B13: =COUNTIF(A19:A44,"*_CA2_*") -> 4 | E13: CP negativos (-) | F13: =COUNTIF(D19:D44,"Negativo*") -> 8
A14: CA3 · Criterio de búsqueda vacío | B14: =COUNTIF(A19:A44,"*_CA3_*") -> 3 | E14: Errores de nivel Baja (solo CP NOK) | F14: =COUNTIFS(F19:F44,"NOK",H19:H44,"*Baja") -> 1
A15: CA4 | B15: =COUNTIF(A19:A44,"*_CA4_*") -> 0 | E15: Errores de nivel Media (solo CP NOK) | F15: =COUNTIFS(F19:F44,"NOK",H19:H44,"*Media") -> 0
A16: Total CP | B16: =SUM(B12:B15) -> 12 | E16: Errores de nivel Alta (solo CP NOK) | F16: =COUNTIFS(F19:F44,"NOK",H19:H44,"*Alta") -> 0
A17: DETALLE (CP)
A18: ID_CP | B18: Campos | C18: Valores | D18: Sentido (+/-) | E18: Resultado esperado | F18: Resultado real (OK / NOK) | G18: Evidencia (enlace) o descripción del fallo | H18: Tipo / Nivel del error | I18: Observación
A19: HE1_HU3_CA1_CP001 | B19: Campo de búsqueda | C19: 10000003 | D19: Positivo (+) | E19: Entonces CA1: el sistema muestra solo a Camila Pérez con sus datos (documento, teléfono, correo, rol, estado). | F19: OK | G19: https://docs.google.com/document/d/1_C8d_ZDSL8BJSZhFncwF0chnvJCmjNM0/edit?usp=drive_link&ouid=103533695958335943637&rtpof=true&sd=true | I19: [Verifica CA1] Precondición: sesión de administrador, lista «Usuarios registrados». Se usan los usuarios de demostración (db:seed). Búsqueda por documento. Evidencia verificada (27/10/2026): el documento tiene una sección para este CP con 2 capturas que muestran los datos ingresados y el resultado esperado.
B20: Acción | C20: Clic en «Buscar»
A21: HE1_HU3_CA1_CP002 | B21: Campo de búsqueda | C21: camila | D21: Positivo (+) | E21: Entonces CA1: el sistema muestra a Camila Pérez (la búsqueda no distingue mayúsculas). | F21: OK | G21: https://docs.google.com/document/d/1_C8d_ZDSL8BJSZhFncwF0chnvJCmjNM0/edit?usp=drive_link&ouid=103533695958335943637&rtpof=true&sd=true | I21: [Verifica CA1] Precondición: sesión de administrador, lista «Usuarios registrados». Se usan los usuarios de demostración (db:seed). Búsqueda por nombre parcial en minúscula. Evidencia verificada (27/10/2026): el documento tiene una sección para este CP con 2 capturas que muestran los datos ingresados y el resultado esperado.
B22: Acción | C22: Clic en «Buscar»
A23: HE1_HU3_CA1_CP003 | B23: Campo de búsqueda | C23: gómez | D23: Positivo (+) | E23: Entonces CA1: el sistema muestra a Andrés Gómez con estado Inactivo. | F23: OK | G23: https://docs.google.com/document/d/1_C8d_ZDSL8BJSZhFncwF0chnvJCmjNM0/edit?usp=drive_link&ouid=103533695958335943637&rtpof=true&sd=true | I23: [Verifica CA1] Precondición: sesión de administrador, lista «Usuarios registrados». Se usan los usuarios de demostración (db:seed). Búsqueda por apellido: aparecen también otros usuarios cuyo nombre contenga «gómez» (por ejemplo Luis Gómez si ya se registró). Evidencia verificada (27/10/2026): el documento tiene una sección para este CP con 2 capturas que muestran los datos ingresados y el resultado esperado.
B24: Acción | C24: Clic en «Buscar»
A25: HE1_HU3_CA2_CP001 | B25: Campo de búsqueda | C25: zzz999 | D25: Negativo (-) | E25: Entonces CA2: la lista queda vacía y muestra el recuadro «No encontramos coincidencias» con el texto «No se encontró ningún usuario con ese nombre o documento.» | F25: OK | G25: https://docs.google.com/document/d/1_C8d_ZDSL8BJSZhFncwF0chnvJCmjNM0/edit?usp=drive_link&ouid=103533695958335943637&rtpof=true&sd=true | I25: [Verifica CA2] Precondición: sesión de administrador, lista «Usuarios registrados». Se usan los usuarios de demostración (db:seed). Texto que no existe. Evidencia verificada (27/10/2026): el documento tiene una sección para este CP con 2 capturas que muestran los datos ingresados y el resultado esperado.
B26: Acción | C26: Clic en «Buscar»
A27: HE1_HU3_CA2_CP002 | B27: Campo de búsqueda | C27: 99999999 | D27: Negativo (-) | E27: Entonces CA2: la lista queda vacía y muestra el recuadro «No encontramos coincidencias» con el texto «No se encontró ningún usuario con ese nombre o documento.» | F27: OK | G27: https://docs.google.com/document/d/1_C8d_ZDSL8BJSZhFncwF0chnvJCmjNM0/edit?usp=drive_link&ouid=103533695958335943637&rtpof=true&sd=true | I27: [Verifica CA2] Precondición: sesión de administrador, lista «Usuarios registrados». Se usan los usuarios de demostración (db:seed). Documento que no existe. Evidencia verificada (27/10/2026): el documento tiene una sección para este CP con 2 capturas que muestran los datos ingresados y el resultado esperado.
B28: Acción | C28: Clic en «Buscar»
A29: HE1_HU3_CA3_CP001 | B29: Campo de búsqueda | C29: (vacío) | D29: Negativo (-) | E29: Entonces CA3: el sistema muestra «Ingresa un nombre o número de documento para buscar.» | F29: OK | G29: https://docs.google.com/document/d/1_C8d_ZDSL8BJSZhFncwF0chnvJCmjNM0/edit?usp=drive_link&ouid=103533695958335943637&rtpof=true&sd=true | I29: [Verifica CA3] Precondición: sesión de administrador, lista «Usuarios registrados». Se usan los usuarios de demostración (db:seed). Campo vacío. Evidencia verificada (27/10/2026): el documento tiene una sección para este CP con 2 capturas que muestran los datos ingresados y el resultado esperado. Observación: junto al mensaje, la pantalla muestra «0 usuarios» y «No encontramos coincidencias»; ver HE1_HU3_CA3_CP003.
B30: Acción | C30: Clic en «Buscar»
A31: HE1_HU3_CA3_CP002 | B31: Campo de búsqueda | C31: (solo espacios) | D31: Negativo (-) | E31: Entonces CA3: el sistema muestra «Ingresa un nombre o número de documento para buscar.» | F31: OK | G31: https://docs.google.com/document/d/1_C8d_ZDSL8BJSZhFncwF0chnvJCmjNM0/edit?usp=drive_link&ouid=103533695958335943637&rtpof=true&sd=true | I31: [Verifica CA3] Precondición: sesión de administrador, lista «Usuarios registrados». Se usan los usuarios de demostración (db:seed). Solo espacios: se trata como vacío. Evidencia verificada (27/10/2026): el documento tiene una sección para este CP con 2 capturas que muestran los datos ingresados y el resultado esperado. Misma observación que CA3_CP001; ver HE1_HU3_CA3_CP003.
B32: Acción | C32: Clic en «Buscar»
A33: CP ADICIONALES PROPUESTOS POR ANÁLISIS DE RIESGOS · EJECUTADOS EL 27/10/2026 en una copia de pruebas (evidencia en Evidencias_E1-HU3_adicionales.docx; un CP marcado PENDIENTE no se pudo ejecutar)
A34: HE1_HU3_CA1_CP004 | B34: Campo de búsqueda | C34: perez (sin tilde) | D34: Positivo (+) | E34: Resultado esperado propuesto (regla pendiente): muestra a Camila Pérez, porque un administrador puede escribir sin tilde. Si se confirma que la búsqueda debe respetar las tildes, el esperado es «No encontramos coincidencias». | F34: NOK | G34: NOK: «perez» no encuentra a «Pérez» (regla R04). Evidencias_E1-HU3_adicionales.docx › HE1_HU3_CA1_CP004 | H34: Funcional (búsqueda) · Baja | I34: [CP adicional – regla pendiente] Riesgo de usabilidad: la búsqueda ignora mayúsculas (CA1_CP002), pero no hay prueba de que ignore tildes; un usuario existente parecería no registrado y podría intentarse registrar de nuevo. Nota de análisis: la consulta usa ILIKE, que distingue tildes; si no lo encuentra y se confirma la regla, registrar NOK (severidad sugerida: Baja). Prioridad de riesgo propuesta: Baja.
B35: Acción | C35: Clic en «Buscar»
A36: HE1_HU3_CA1_CP005 | B36: Canal | C36: API: GET http://localhost:3000/api/usuarios?buscar=camila | D36: Negativo (-) | E36: Validación adicional: respuesta 403 «No tienes permiso para realizar esta acción.»; no se devuelven teléfono ni correo. Además, GET http://localhost:3000/api/asignaciones/usuarios no debe incluir «telefono» ni «correo». | F36: OK | G36: Evidencias_E1-HU3_adicionales.docx › HE1_HU3_CA1_CP005 | I36: [CP adicional] Riesgo de privacidad: teléfono y correo son datos personales y la consulta de usuarios es del administrador. Prioridad de riesgo propuesta: Alta.
B37: Token | C37: Sesión de Entrenador Demo (10000002 / Saiya2026)
A38: HE1_HU3_CA2_CP003 | B38: Campo de búsqueda | C38: % | D38: Negativo (-) | E38: Entonces CA2 (variante): muestra «No encontramos coincidencias» con «No se encontró ningún usuario con ese nombre o documento.» (ningún nombre ni documento contiene «%»); no debe listar a todos los usuarios. | F38: OK | G38: Evidencias_E1-HU3_adicionales.docx › HE1_HU3_CA2_CP003 | I38: [CP adicional] Riesgo: en SQL «%» es comodín; si no se escapa, la búsqueda devuelve todo el directorio y deja de filtrar. Probar también «_». Prioridad de riesgo propuesta: Media.
B39: Acción | C39: Clic en «Buscar»
A40: HE1_HU3_CA2_CP004 | B40: Campo de búsqueda | C40: ' OR '1'='1 | D40: Negativo (-) | E40: Entonces CA2 (variante): muestra «No encontramos coincidencias»; no aparece error del servidor y, al pulsar «Limpiar», el directorio muestra todos los usuarios con sus datos intactos. | F40: OK | G40: Evidencias_E1-HU3_adicionales.docx › HE1_HU3_CA2_CP004 | I40: [CP adicional] Riesgo de seguridad (inyección SQL) en el único texto libre que llega a una consulta. Prioridad de riesgo propuesta: Alta.
B41: Acción | C41: Clic en «Buscar»; luego «Limpiar»
...

Sheet E1-HU4
A1: DISEÑO DE CASOS DE PRUEBA (CP) — SAIYAGYM · E1-HU4 Gestionar estado de usuarios
A2: Rol que ejecuta: Administrador. Celdas amarillas = para completar al ejecutar. Alcance y estadísticas se calculan solos.
A4: GENERALIDADES DE LA PRUEBA | E4: ESTADÍSTICAS
A5: Fecha | B5: 2026-10-20 | E5: Total CP diseñados | F5: =COUNTIF(A19:A52,"HE?_HU?_CA?_CP???") -> 11
A6: HU | B6: E1-HU4 — Gestionar estado de usuarios | E6: Total CP ejecutados (OK + NOK) | F6: =COUNTIF(F19:F52,"OK")+COUNTIF(F19:F52,"NOK") -> 11
A7: Módulo | B7: Gestión de usuarios (Sprint 1) | E7: CP con resultado OK | F7: =COUNTIF(F19:F52,"OK") -> 11
A8: No. SP | E8: CP con resultado NOK | F8: =COUNTIF(F19:F52,"NOK") -> 0
A9: Iteración | E9: % OK sobre ejecutados | F9: =IF(F6=0,"Sin ejecutados",F7/F6) -> 1
A10: Tipo de prueba | B10: Funcional | E10: % NOK sobre ejecutados | F10: =IF(F6=0,"Sin ejecutados",F8/F6) -> 0
A11: Alcance (CP por criterio de aceptación) | E11: CP pendientes de ejecutar | F11: =F5-F6 -> 0
A12: CA1 · Activar usuario | B12: =COUNTIF(A19:A52,"*_CA1_*") -> 3 | E12: CP positivos (+) | F12: =COUNTIF(D19:D52,"Positivo*") -> 5
A13: CA2 · Inactivar usuario | B13: =COUNTIF(A19:A52,"*_CA2_*") -> 4 | E13: CP negativos (-) | F13: =COUNTIF(D19:D52,"Negativo*") -> 6
A14: CA3 · Usuario no encontrado | B14: =COUNTIF(A19:A52,"*_CA3_*") -> 4 | E14: Errores de nivel Baja (solo CP NOK) | F14: =COUNTIFS(F19:F52,"NOK",H19:H52,"*Baja") -> 0
A15: CA4 | B15: =COUNTIF(A19:A52,"*_CA4_*") -> 0 | E15: Errores de nivel Media (solo CP NOK) | F15: =COUNTIFS(F19:F52,"NOK",H19:H52,"*Media") -> 0
A16: Total CP | B16: =SUM(B12:B15) -> 11 | E16: Errores de nivel Alta (solo CP NOK) | F16: =COUNTIFS(F19:F52,"NOK",H19:H52,"*Alta") -> 0
A17: DETALLE (CP)
A18: ID_CP | B18: Campos | C18: Valores | D18: Sentido (+/-) | E18: Resultado esperado | F18: Resultado real (OK / NOK) | G18: Evidencia (enlace) o descripción del fallo | H18: Tipo / Nivel del error | I18: Observación
A19: HE1_HU4_CA1_CP001 | B19: Usuario | C19: Andrés Gómez (10000004) | D19: Positivo (+) | E19: Entonces CA1: el sistema cambia el estado a Activo y muestra «Andrés Gómez fue activado correctamente.» | F19: OK | G19: https://docs.google.com/document/d/1-qbGi9E85ciCa6cZzggyylpTzn9xzpVn/edit?usp=drive_link&ouid=103533695958335943637&rtpof=true&sd=true | I19: [Verifica CA1] Precondición: sesión de administrador, lista «Usuarios registrados». Usuario inactivo de demostración (db:seed). Evidencia verificada (27/10/2026): el documento tiene una sección para este CP con 2 capturas que muestran los datos ingresados y el resultado esperado.
B20: Estado actual | C20: Inactivo
B21: Acción | C21: Clic en «Activar»
A22: HE1_HU4_CA1_CP002 | B22: Usuario | C22: Pedro Ruiz (55550001) | D22: Positivo (+) | E22: Entonces CA1: el sistema cambia el estado a Activo y muestra «Pedro Ruiz fue activado correctamente.» | F22: OK | G22: https://docs.google.com/document/d/1-qbGi9E85ciCa6cZzggyylpTzn9xzpVn/edit?usp=drive_link&ouid=103533695958335943637&rtpof=true&sd=true | I22: [Verifica CA1] Precondición: sesión de administrador, lista «Usuarios registrados». Precondición extra: Pedro ya fue inactivado en CA2_CP001. Evidencia verificada (27/10/2026): el documento tiene una sección para este CP con 2 capturas que muestran los datos ingresados y el resultado esperado.
B23: Estado actual | C23: Inactivo
B24: Acción | C24: Clic en «Activar»
A25: HE1_HU4_CA2_CP001 | B25: Usuario | C25: Pedro Ruiz (55550001) | D25: Positivo (+) | E25: Entonces CA2: el sistema cambia el estado a Inactivo y muestra «Pedro Ruiz fue inactivado correctamente.» | F25: OK | G25: https://docs.google.com/document/d/1-qbGi9E85ciCa6cZzggyylpTzn9xzpVn/edit?usp=drive_link&ouid=103533695958335943637&rtpof=true&sd=true | I25: [Verifica CA2] Precondición: sesión de administrador, lista «Usuarios registrados». El registro NO se elimina: solo cambia el estado. Evidencia verificada (27/10/2026): el documento tiene una sección para este CP con 2 capturas que muestran los datos ingresados y el resultado esperado.
B26: Estado actual | C26: Activo
B27: Acción | C27: Clic en «Inactivar»
A28: HE1_HU4_CA2_CP002 | B28: Usuario | C28: Laura Mora Díaz (55550002) | D28: Positivo (+) | E28: Entonces CA2: el sistema cambia el estado a Inactivo y muestra «Laura Mora Díaz fue inactivado correctamente.» | F28: OK | G28: https://docs.google.com/document/d/1-qbGi9E85ciCa6cZzggyylpTzn9xzpVn/edit?usp=drive_link&ouid=103533695958335943637&rtpof=true&sd=true | I28: [Verifica CA2] Precondición: sesión de administrador, lista «Usuarios registrados». Después se vuelve a activar para no afectar otras pruebas. Evidencia verificada (27/10/2026): el documento tiene una sección para este CP con 2 capturas que muestran los datos ingresados y el resultado esperado.
B29: Estado actual | C29: Activo
B30: Acción | C30: Clic en «Inactivar»
A31: HE1_HU4_CA3_CP001 | B31: Usuario | C31: Temporal 2 (55559998) | D31: Negativo (-) | E31: Entonces CA3: el sistema rechaza el cambio y muestra «El usuario no existe.» | F31: OK | G31: https://docs.google.com/document/d/1-qbGi9E85ciCa6cZzggyylpTzn9xzpVn/edit?usp=drive_link&ouid=103533695958335943637&rtpof=true&sd=true | I31: [Verifica CA3] Precondición: sesión de administrador, lista «Usuarios registrados». Usuario temporal 55559998: se registra, y con la fila visible se borra de la base de datos con SQL; luego se pulsa «Inactivar» (pasos en el documento Pasos_E1-HU4). Evidencia verificada (27/10/2026): el documento tiene una sección para este CP con 2 capturas que muestran los datos ingresados y el resultado esperado.
B32: Estado actual | C32: Activo (la fila sigue en pantalla pero ya se borró de la base de datos)
B33: Acción | C33: Clic en «Inactivar»
A34: HE1_HU4_CA3_CP002 | B34: Usuario | C34: Administrador Demo (10000001): la fila del propio administrador | D34: Negativo (-) | E34: Entonces CA3: el botón «Inactivar» de esa fila aparece deshabilitado y al pasar el cursor muestra «No puedes cambiar el estado de tu propio usuario»; no se puede inactivar. | F34: OK | G34: https://docs.google.com/document/d/1-qbGi9E85ciCa6cZzggyylpTzn9xzpVn/edit?usp=drive_link&ouid=103533695958335943637&rtpof=true&sd=true | I34: [CP adicional] Precondición: sesión de administrador, lista «Usuarios registrados». CP adicional: el administrador no puede inactivarse a sí mismo (el sistema lo impide desde la pantalla). Evidencia parcial (27/10/2026): hay una sola captura; muestra «Inactivar» deshabilitado en la fila del administrador, pero no el texto emergente «No puedes cambiar el estado de tu propio usuario». Capturar de nuevo con el cursor sobre el botón. Nota: está clasificado en CA3 (usuario no encontrado) aunque es otra regla; se conserva el ID para no romper la relación con la evidencia. La regla en el servidor se prueba en HE1_HU4_CA3_CP003.
B35: Estado actual | C35: Activo
B36: Acción | C36: Intentar pulsar «Inactivar»
A37: CP ADICIONALES PROPUESTOS POR ANÁLISIS DE RIESGOS · EJECUTADOS EL 27/10/2026 en una copia de pruebas (evidencia en Evidencias_E1-HU4_adicionales.docx; un CP marcado PENDIENTE no se pudo ejecutar)
A38: HE1_HU4_CA1_CP003 | B38: Usuario | C38: Pedro Ruiz (55550001) con «Cardio básico» vigente (E2-HU2 CA1_CP002) | D38: Positivo (+) | E38: Validación adicional: tras activarlo, Pedro ve «TU RUTINA ACTUAL» con «Cardio básico» y la misma fecha de asignación; inactivar no borra ni altera su historial. | F38: OK | G38: Evidencias_E1-HU4_adicionales.docx › HE1_HU4_CA1_CP003 | I38: [CP adicional] Riesgo de integridad entre módulos: el CA2 dice que el registro no se elimina; este CP comprueba que tampoco se pierdan sus relaciones. Ejecutar después de E2-HU2. Regla pendiente: si al inactivar debe retirarse la rutina, el esperado cambia. Prioridad de riesgo propuesta: Media.
B39: Acción | C39: Inactivar y luego Activar
B40: Verificación | C40: Pedro inicia sesión (Nueva2026) → «Mi rutina»
A41: HE1_HU4_CA2_CP003 | B41: Usuario | C41: Pedro Ruiz (55550001), Activo, con sesión abierta en «Mi rutina» en otro navegador | D41: Negativo (-) | E41: Validación adicional: Pedro ya no ve su rutina: la recarga muestra «Tu usuario está inactivo. Comunícate con el administrador.» o lo devuelve al inicio de sesión. | F41: OK | G41: Evidencias_E1-HU4_adicionales.docx › HE1_HU4_CA2_CP003 | I41: [CP adicional] Riesgo: estado que cambia mientras se usa. Si el estado solo se revisara al iniciar sesión, un usuario inactivado seguiría entrando hasta 8 h. Al terminar, activar a Pedro. Prioridad de riesgo propuesta: Alta.
...

Sheet E2-HU1
A1: DISEÑO DE CASOS DE PRUEBA (CP) — SAIYAGYM · E2-HU1 Crear rutina de entrenamiento
A2: Rol que ejecuta: Entrenador. Celdas amarillas = para completar al ejecutar. Alcance y estadísticas se calculan solos.
A4: GENERALIDADES DE LA PRUEBA | E4: ESTADÍSTICAS
A5: Fecha | B5: 2026-10-20 | E5: Total CP diseñados | F5: =COUNTIF(A19:A66,"HE?_HU?_CA?_CP???") -> 16
A6: HU | B6: E2-HU1 — Crear rutina de entrenamiento | E6: Total CP ejecutados (OK + NOK) | F6: =COUNTIF(F19:F66,"OK")+COUNTIF(F19:F66,"NOK") -> 16
A7: Módulo | B7: Gestión de rutinas (Sprint 2) | E7: CP con resultado OK | F7: =COUNTIF(F19:F66,"OK") -> 15
A8: No. SP | E8: CP con resultado NOK | F8: =COUNTIF(F19:F66,"NOK") -> 1
A9: Iteración | E9: % OK sobre ejecutados | F9: =IF(F6=0,"Sin ejecutados",F7/F6) -> 0.9375
A10: Tipo de prueba | B10: Funcional | E10: % NOK sobre ejecutados | F10: =IF(F6=0,"Sin ejecutados",F8/F6) -> 0.0625
A11: Alcance (CP por criterio de aceptación) | E11: CP pendientes de ejecutar | F11: =F5-F6 -> 0
A12: CA1 · Creación exitosa | B12: =COUNTIF(A19:A66,"*_CA1_*") -> 6 | E12: CP positivos (+) | F12: =COUNTIF(D19:D66,"Positivo*") -> 3
A13: CA2 · Datos incompletos | B13: =COUNTIF(A19:A66,"*_CA2_*") -> 8 | E13: CP negativos (-) | F13: =COUNTIF(D19:D66,"Negativo*") -> 13
A14: CA3 · Ejercicio no seleccionado | B14: =COUNTIF(A19:A66,"*_CA3_*") -> 2 | E14: Errores de nivel Baja (solo CP NOK) | F14: =COUNTIFS(F19:F66,"NOK",H19:H66,"*Baja") -> 0
A15: CA4 | B15: =COUNTIF(A19:A66,"*_CA4_*") -> 0 | E15: Errores de nivel Media (solo CP NOK) | F15: =COUNTIFS(F19:F66,"NOK",H19:H66,"*Media") -> 1
A16: Total CP | B16: =SUM(B12:B15) -> 16 | E16: Errores de nivel Alta (solo CP NOK) | F16: =COUNTIFS(F19:F66,"NOK",H19:H66,"*Alta") -> 0
A17: DETALLE (CP)
A18: ID_CP | B18: Campos | C18: Valores | D18: Sentido (+/-) | E18: Resultado esperado | F18: Resultado real (OK / NOK) | G18: Evidencia (enlace) o descripción del fallo | H18: Tipo / Nivel del error | I18: Observación
A19: HE2_HU1_CA1_CP001 | B19: Nombre de la rutina | C19: Fuerza tren superior | D19: Positivo (+) | E19: Entonces CA1: el sistema crea la rutina y muestra «Rutina registrada correctamente.» | F19: OK | G19: https://docs.google.com/document/d/1NfQHTG3vGCu2g09koHiX7udgol7BF719/edit?usp=drive_link&ouid=103533695958335943637&rtpof=true&sd=true | I19: [Verifica CA1] Precondición: sesión de entrenador (10000002), pantalla Rutinas, formulario «Nueva rutina». Rutina de 2 ejercicios. Se usa luego en E2-HU2 y E2-HU4. Evidencia verificada (27/10/2026): el documento tiene una sección para este CP con 2 capturas que muestran los datos ingresados y el resultado esperado.
B20: Objetivo | C20: Ganar fuerza y masa muscular
B21: Ejercicio 1 | C21: Press banca · 4 series x 10 rep.
B22: Ejercicio 2 | C22: Remo con barra · 4 series x 10 rep.
A23: HE2_HU1_CA1_CP002 | B23: Nombre de la rutina | C23: Cardio básico | D23: Positivo (+) | E23: Entonces CA1: el sistema crea la rutina y muestra «Rutina registrada correctamente.» | F23: OK | G23: https://docs.google.com/document/d/1NfQHTG3vGCu2g09koHiX7udgol7BF719/edit?usp=drive_link&ouid=103533695958335943637&rtpof=true&sd=true | I23: [Verifica CA1] Precondición: sesión de entrenador (10000002), pantalla Rutinas, formulario «Nueva rutina». Rutina con un solo ejercicio (mínimo permitido). Evidencia verificada (27/10/2026): el documento tiene una sección para este CP con 2 capturas que muestran los datos ingresados y el resultado esperado.
B24: Objetivo | C24: Mejorar resistencia
B25: Ejercicio 1 | C25: Sentadilla libre · 3 series x 15 rep.
A26: HE2_HU1_CA1_CP003 | B26: Nombre de la rutina | C26: Pierna intensiva | D26: Positivo (+) | E26: Entonces CA1: el sistema crea la rutina y muestra «Rutina registrada correctamente.» | F26: OK | G26: https://docs.google.com/document/d/1NfQHTG3vGCu2g09koHiX7udgol7BF719/edit?usp=drive_link&ouid=103533695958335943637&rtpof=true&sd=true | I26: [Verifica CA1] Precondición: sesión de entrenador (10000002), pantalla Rutinas, formulario «Nueva rutina». Valores límite: 20 series y 200 repeticiones (máximos permitidos). Evidencia verificada (27/10/2026): el documento tiene una sección para este CP con 2 capturas que muestran los datos ingresados y el resultado esperado.
B27: Objetivo | C27: Aumentar resistencia muscular
B28: Ejercicio 1 | C28: Prensa de piernas · 20 series x 200 rep.
A29: HE2_HU1_CA2_CP001 | B29: Nombre de la rutina | C29: (vacío) | D29: Negativo (-) | E29: Entonces CA2: el sistema rechaza el registro y muestra «Faltan datos obligatorios de la rutina: Nombre de la rutina.» | F29: OK | G29: https://docs.google.com/document/d/1NfQHTG3vGCu2g09koHiX7udgol7BF719/edit?usp=drive_link&ouid=103533695958335943637&rtpof=true&sd=true | I29: [Verifica CA2] Precondición: sesión de entrenador (10000002), pantalla Rutinas, formulario «Nueva rutina». Nombre vacío. Evidencia verificada (27/10/2026): el documento tiene una sección para este CP con 2 capturas que muestran los datos ingresados y el resultado esperado.
B30: Objetivo | C30: Ganar fuerza
B31: Ejercicio 1 | C31: Press banca · 4 series x 10 rep.
A32: HE2_HU1_CA2_CP002 | B32: Nombre de la rutina | C32: Fuerza tren superior | D32: Negativo (-) | E32: Entonces CA2: el sistema rechaza el registro y muestra «Faltan datos obligatorios de la rutina: Objetivo.» | F32: OK | G32: https://docs.google.com/document/d/1NfQHTG3vGCu2g09koHiX7udgol7BF719/edit?usp=drive_link&ouid=103533695958335943637&rtpof=true&sd=true | I32: [Verifica CA2] Precondición: sesión de entrenador (10000002), pantalla Rutinas, formulario «Nueva rutina». Objetivo vacío. Evidencia verificada (27/10/2026): el documento tiene una sección para este CP con 2 capturas que muestran los datos ingresados y el resultado esperado.
B33: Objetivo | C33: (vacío)
B34: Ejercicio 1 | C34: Press banca · 4 series x 10 rep.
A35: HE2_HU1_CA2_CP003 | B35: Nombre de la rutina | C35: (vacío) | D35: Negativo (-) | E35: Entonces CA2: el sistema rechaza el registro y muestra «Faltan datos obligatorios de la rutina: Nombre de la rutina, Objetivo.» | F35: OK | G35: https://docs.google.com/document/d/1NfQHTG3vGCu2g09koHiX7udgol7BF719/edit?usp=drive_link&ouid=103533695958335943637&rtpof=true&sd=true | I35: [Verifica CA2] Precondición: sesión de entrenador (10000002), pantalla Rutinas, formulario «Nueva rutina». Nombre y objetivo vacíos. Evidencia verificada (27/10/2026): el documento tiene una sección para este CP con 2 capturas que muestran los datos ingresados y el resultado esperado.
B36: Objetivo | C36: (vacío)
B37: Ejercicio 1 | C37: Press banca · 4 series x 10 rep.
A38: HE2_HU1_CA2_CP004 | B38: Nombre de la rutina | C38: Rutina X | D38: Negativo (-) | E38: Entonces CA2: el sistema rechaza el registro y muestra «El ejercicio 1 no es válido: series entre 1 y 20, repeticiones entre 1 y 200 y nombre de máximo 120 caracteres.» | F38: OK | G38: https://docs.google.com/document/d/1NfQHTG3vGCu2g09koHiX7udgol7BF719/edit?usp=drive_link&ouid=103533695958335943637&rtpof=true&sd=true | I38: [CP adicional] Precondición: sesión de entrenador (10000002), pantalla Rutinas, formulario «Nueva rutina». CP adicional: 21 series (fuera del límite). Evidencia verificada (27/10/2026): el documento tiene una sección para este CP con 2 capturas que muestran los datos ingresados y el resultado esperado.
B39: Objetivo | C39: Objetivo X
B40: Ejercicio 1 | C40: Press banca · 21 series x 10 rep.
A41: HE2_HU1_CA2_CP005 | B41: Nombre de la rutina | C41: Rutina X | D41: Negativo (-) | E41: Entonces CA2: el sistema rechaza el registro y muestra «Completa el nombre, las series y las repeticiones del ejercicio 1.» | F41: OK | G41: https://docs.google.com/document/d/1NfQHTG3vGCu2g09koHiX7udgol7BF719/edit?usp=drive_link&ouid=103533695958335943637&rtpof=true&sd=true | I41: [CP adicional] Precondición: sesión de entrenador (10000002), pantalla Rutinas, formulario «Nueva rutina». CP adicional: repeticiones vacías. Evidencia verificada (27/10/2026): el documento tiene una sección para este CP con 2 capturas que muestran los datos ingresados y el resultado esperado.
...

Sheet E2-HU2
A1: DISEÑO DE CASOS DE PRUEBA (CP) — SAIYAGYM · E2-HU2 Asignar rutina a usuario
A2: Rol que ejecuta: Entrenador. Celdas amarillas = para completar al ejecutar. Alcance y estadísticas se calculan solos.
A4: GENERALIDADES DE LA PRUEBA | E4: ESTADÍSTICAS
A5: Fecha | B5: 2026-10-20 | E5: Total CP diseñados | F5: =COUNTIF(A19:A60,"HE?_HU?_CA?_CP???") -> 13
A6: HU | B6: E2-HU2 — Asignar rutina a usuario | E6: Total CP ejecutados (OK + NOK) | F6: =COUNTIF(F19:F60,"OK")+COUNTIF(F19:F60,"NOK") -> 13
A7: Módulo | B7: Gestión de rutinas (Sprint 2) | E7: CP con resultado OK | F7: =COUNTIF(F19:F60,"OK") -> 9
A8: No. SP | E8: CP con resultado NOK | F8: =COUNTIF(F19:F60,"NOK") -> 4
A9: Iteración | E9: % OK sobre ejecutados | F9: =IF(F6=0,"Sin ejecutados",F7/F6) -> 0.69230769
A10: Tipo de prueba | B10: Funcional | E10: % NOK sobre ejecutados | F10: =IF(F6=0,"Sin ejecutados",F8/F6) -> 0.30769231
A11: Alcance (CP por criterio de aceptación) | E11: CP pendientes de ejecutar | F11: =F5-F6 -> 0
A12: CA1 · Asignación exitosa | B12: =COUNTIF(A19:A60,"*_CA1_*") -> 5 | E12: CP positivos (+) | F12: =COUNTIF(D19:D60,"Positivo*") -> 3
A13: CA2 · Usuario no seleccionado | B13: =COUNTIF(A19:A60,"*_CA2_*") -> 1 | E13: CP negativos (-) | F13: =COUNTIF(D19:D60,"Negativo*") -> 10
A14: CA3 · Usuario no disponible | B14: =COUNTIF(A19:A60,"*_CA3_*") -> 3 | E14: Errores de nivel Baja (solo CP NOK) | F14: =COUNTIFS(F19:F60,"NOK",H19:H60,"*Baja") -> 3
A15: CA4 · Rutina no seleccionada | B15: =COUNTIF(A19:A60,"*_CA4_*") -> 4 | E15: Errores de nivel Media (solo CP NOK) | F15: =COUNTIFS(F19:F60,"NOK",H19:H60,"*Media") -> 1
A16: Total CP | B16: =SUM(B12:B15) -> 13 | E16: Errores de nivel Alta (solo CP NOK) | F16: =COUNTIFS(F19:F60,"NOK",H19:H60,"*Alta") -> 0
A17: DETALLE (CP)
A18: ID_CP | B18: Campos | C18: Valores | D18: Sentido (+/-) | E18: Resultado esperado | F18: Resultado real (OK / NOK) | G18: Evidencia (enlace) o descripción del fallo | H18: Tipo / Nivel del error | I18: Observación
A19: HE2_HU2_CA1_CP001 | B19: Usuario | C19: Camila Pérez | D19: Positivo (+) | E19: Entonces CA1: el sistema asigna la rutina y muestra «La rutina "Fuerza tren superior" fue asignada a Camila Pérez correctamente.» | F19: OK | G19: https://docs.google.com/document/d/1lRqV1zrO9mUMZ58Zv8bgMuRSpJwCJOTD/edit?usp=drive_link&ouid=103533695958335943637&rtpof=true&sd=true | I19: [Verifica CA1] Precondición: sesión de entrenador, tarjeta «Asignar rutina a un usuario»; existen las rutinas de E2-HU1. Evidencia verificada (27/10/2026): el documento tiene una sección para este CP con 2 capturas que muestran los datos ingresados y el resultado esperado.
B20: Rutina | C20: Fuerza tren superior
B21: Acción | C21: Clic en «Asignar»
A22: HE2_HU2_CA1_CP002 | B22: Usuario | C22: Pedro Ruiz | D22: Positivo (+) | E22: Entonces CA1: el sistema asigna la rutina y muestra «La rutina "Cardio básico" fue asignada a Pedro Ruiz correctamente.» | F22: OK | G22: https://docs.google.com/document/d/1lRqV1zrO9mUMZ58Zv8bgMuRSpJwCJOTD/edit?usp=drive_link&ouid=103533695958335943637&rtpof=true&sd=true | I22: [Verifica CA1] Precondición: sesión de entrenador, tarjeta «Asignar rutina a un usuario»; existen las rutinas de E2-HU1. Pedro debe estar Activo (E1-HU4 CA1_CP002). Evidencia verificada (27/10/2026): el documento tiene una sección para este CP con 2 capturas que muestran los datos ingresados y el resultado esperado.
B23: Rutina | C23: Cardio básico
B24: Acción | C24: Clic en «Asignar»
A25: HE2_HU2_CA1_CP003 | B25: Usuario | C25: Camila Pérez | D25: Positivo (+) | E25: Entonces CA1: el sistema asigna la nueva rutina; la anterior queda como histórico y Camila ve solo «Cardio básico» en Mi rutina. | F25: OK | G25: https://docs.google.com/document/d/1lRqV1zrO9mUMZ58Zv8bgMuRSpJwCJOTD/edit?usp=drive_link&ouid=103533695958335943637&rtpof=true&sd=true | I25: [Verifica CA1] Precondición: sesión de entrenador, tarjeta «Asignar rutina a un usuario»; existen las rutinas de E2-HU1. Reasignación: Camila ya tenía «Fuerza tren superior». Al terminar queda con «Cardio básico». Evidencia verificada (27/10/2026): el documento tiene una sección para este CP con 2 capturas que muestran los datos ingresados y el resultado esperado. La captura muestra «Asignada a»: Cardio básico 2 y Fuerza tren superior 0, coherente con la reasignación. Que Camila vea solo «Cardio básico» se comprueba en E2-HU4 CA4_CP002.
B26: Rutina | C26: Cardio básico
B27: Acción | C27: Clic en «Asignar»
A28: HE2_HU2_CA2_CP001 | B28: Usuario | C28: Selecciona un usuario | D28: Negativo (-) | E28: Entonces CA2: el sistema rechaza la asignación y muestra «Selecciona un usuario para asignarle la rutina.» | F28: OK | G28: https://docs.google.com/document/d/1lRqV1zrO9mUMZ58Zv8bgMuRSpJwCJOTD/edit?usp=drive_link&ouid=103533695958335943637&rtpof=true&sd=true | I28: [Verifica CA2] Precondición: sesión de entrenador, tarjeta «Asignar rutina a un usuario»; existen las rutinas de E2-HU1. No se elige usuario. Evidencia verificada (27/10/2026): el documento tiene una sección para este CP con 2 capturas que muestran los datos ingresados y el resultado esperado.
