Workbook

Sheet Guía
A1: Casos de prueba (CP) — Guía del formato
A3: HOJAS
A4: Resumen | B4: Una fila por historia: CP diseñados, positivos, negativos, ejecutados, OK/NOK y si cumple el mínimo de la profe.
A5: E1-HU1 … E2-HU4 | B5: Una hoja por historia de usuario de los Sprints 1 y 2, con los casos escritos con datos reales de SAIYAGYM y los mensajes exactos que muestra el sistema.
A6: Formato en blanco | B6: Plantilla vacía para las historias de los siguientes sprints.
A7: TIPO DE PRUEBA
A8: Funcionales | B8: Prueban lo que el sistema debe hacer según cada historia y sus criterios de aceptación, sin mirar el código. Este formato es de ese tipo. Las pruebas unitarias las hace el desarrollador en el código, y las de aceptación las valida el cliente.
A9: CÓMO LEER UNA HOJA
A10: Generalidades | B10: Fecha, historia (HU), módulo, No. SP, iteración y tipo de prueba. Amarillo = para completar.
A11: Alcance | B11: Cuántos CP tiene cada criterio de aceptación (CA). Se cuenta solo, leyendo el ID_CP.
A12: ID_CP | B12: HE1_HU1_CA1_CP001 = Épica 1, historia 1, criterio de aceptación 1, caso 001.
A13: Campos / Valores | B13: Cada dato que se ingresa (o se hace) y el valor exacto que se usa. Los renglones del mismo CP están agrupados.
A14: Sentido (+/-) | B14: Positivo (+): el dato es válido y debe salir bien. Negativo (-): el dato es inválido o la situación no permite la acción y el sistema debe rechazarla.
A15: Resultado esperado | B15: «Entonces CAn» + lo que dice el criterio + el mensaje exacto de la pantalla.
A16: Observación | B16: Precondición (qué debe existir antes), cómo probarlo (pantalla, API o base de datos) y si el CP es adicional al criterio.
A17: Al ejecutar
A18: Pasos | B18: Elige OK o NOK en «Resultado real». Pon el enlace de la evidencia (captura o video) o describe el fallo. Si es NOK, elige el nivel del error (Baja, Media, Alta). Las estadísticas se actualizan solas.
A19: Orden de ejecución | B19: Algunos CP dependen de otros (ej. E2-HU2 usa las rutinas de E2-HU1). Se ejecutan en el orden E1-HU1 → E2-HU4; la columna Observación lo indica.
A20: Casos con preparación en la base de datos | B20: «Usuario no encontrado» (E1-HU2 y E1-HU4) y «Rutina no encontrada» (E2-HU3): se deja el registro abierto en pantalla, se borra de la base de datos con SQL y luego se pulsa Guardar o Inactivar. «Rutina no disponible» (E2-HU4) se prepara con un UPDATE. Los pasos están en los documentos Pasos_.
A21: PARA CONFIRMAR CON LA PROFESORA
A22: 1 | B22: ¿«No. SP» es número de sprint o puntos de la historia? Lo dejé libre.
A23: 2 | B23: El «=PU» junto al ID y el esquema de la derecha de la pizarra («X3CP», «Ex», «Rg») no se leían con certeza; no los apliqué.
A24: 3 | B24: La regla «mínimo 2 positivos y 1 negativo» la apliqué por historia (el Resumen la verifica). Si es por criterio de aceptación, hay que agregar CP en los criterios que son solo negativos (ej. «Usuario duplicado»).
A25: 4 | B25: Los CP marcados «CP adicional» van más allá del criterio (validar formato de correo, contraseña, límites). Se pueden borrar si prefieren ceñirse a los criterios.
A26: 5 | B26: Nivel del error: Baja / Media / Alta (en la pizarra se ve «Baja»). Si usan otra escala, se cambia en la lista de la columna.
A27: 6 | B27: Los CP no están ejecutados: Resultado real, evidencia, nivel del error quedan en blanco hasta correr las pruebas.
A28: 7 | B28: En el sistema, las historias E1-HU2 y E1-HU3 están numeradas al revés que en el documento de HU (en código: HU2 = consultar, HU3 = actualizar). Aquí se usó la numeración del documento de HU.

Sheet Resumen
A1: RESUMEN DE CASOS DE PRUEBA — SAIYAGYM · Sprint 1 y Sprint 2
A2: Todo se calcula con fórmulas desde cada hoja de historia. Regla de la profe: mínimo 2 positivos y 1 negativo por historia.
A4: Historia | B4: Nombre | C4: Sprint | D4: CP diseñados | E4: Positivos (+) | F4: Negativos (-) | G4: Ejecutados | H4: OK | I4: NOK | J4: Pendientes | K4: ¿Cumple mínimo 2(+) y 1(-)?
A5: E1-HU1 | B5: Registrar usuarios | C5: Sprint 1 | D5: ='E1-HU1'!F5 -> 16 | E5: ='E1-HU1'!F12 -> 4 | F5: ='E1-HU1'!F13 -> 12 | G5: ='E1-HU1'!F6 -> 16 | H5: ='E1-HU1'!F7 -> 16 | I5: ='E1-HU1'!F8 -> 0 | J5: ='E1-HU1'!F11 -> 0 | K5: =IF(AND(E5>=2,F5>=1),"Sí cumple","NO cumple") -> Sí cumple
A6: E1-HU2 | B6: Actualizar información de usuarios | C6: Sprint 1 | D6: ='E1-HU2'!F5 -> 9 | E6: ='E1-HU2'!F12 -> 3 | F6: ='E1-HU2'!F13 -> 6 | G6: ='E1-HU2'!F6 -> 9 | H6: ='E1-HU2'!F7 -> 9 | I6: ='E1-HU2'!F8 -> 0 | J6: ='E1-HU2'!F11 -> 0 | K6: =IF(AND(E6>=2,F6>=1),"Sí cumple","NO cumple") -> Sí cumple
A7: E1-HU3 | B7: Consultar información de usuarios | C7: Sprint 1 | D7: ='E1-HU3'!F5 -> 7 | E7: ='E1-HU3'!F12 -> 3 | F7: ='E1-HU3'!F13 -> 4 | G7: ='E1-HU3'!F6 -> 7 | H7: ='E1-HU3'!F7 -> 7 | I7: ='E1-HU3'!F8 -> 0 | J7: ='E1-HU3'!F11 -> 0 | K7: =IF(AND(E7>=2,F7>=1),"Sí cumple","NO cumple") -> Sí cumple
A8: E1-HU4 | B8: Gestionar estado de usuarios | C8: Sprint 1 | D8: ='E1-HU4'!F5 -> 6 | E8: ='E1-HU4'!F12 -> 4 | F8: ='E1-HU4'!F13 -> 2 | G8: ='E1-HU4'!F6 -> 6 | H8: ='E1-HU4'!F7 -> 6 | I8: ='E1-HU4'!F8 -> 0 | J8: ='E1-HU4'!F11 -> 0 | K8: =IF(AND(E8>=2,F8>=1),"Sí cumple","NO cumple") -> Sí cumple
A9: E2-HU1 | B9: Crear rutina de entrenamiento | C9: Sprint 2 | D9: ='E2-HU1'!F5 -> 10 | E9: ='E2-HU1'!F12 -> 3 | F9: ='E2-HU1'!F13 -> 7 | G9: ='E2-HU1'!F6 -> 10 | H9: ='E2-HU1'!F7 -> 10 | I9: ='E2-HU1'!F8 -> 0 | J9: ='E2-HU1'!F11 -> 0 | K9: =IF(AND(E9>=2,F9>=1),"Sí cumple","NO cumple") -> Sí cumple
A10: E2-HU2 | B10: Asignar rutina a usuario | C10: Sprint 2 | D10: ='E2-HU2'!F5 -> 7 | E10: ='E2-HU2'!F12 -> 3 | F10: ='E2-HU2'!F13 -> 4 | G10: ='E2-HU2'!F6 -> 7 | H10: ='E2-HU2'!F7 -> 7 | I10: ='E2-HU2'!F8 -> 0 | J10: ='E2-HU2'!F11 -> 0 | K10: =IF(AND(E10>=2,F10>=1),"Sí cumple","NO cumple") -> Sí cumple
A11: E2-HU3 | B11: Modificar rutina de entrenamiento | C11: Sprint 2 | D11: ='E2-HU3'!F5 -> 7 | E11: ='E2-HU3'!F12 -> 3 | F11: ='E2-HU3'!F13 -> 4 | G11: ='E2-HU3'!F6 -> 7 | H11: ='E2-HU3'!F7 -> 7 | I11: ='E2-HU3'!F8 -> 0 | J11: ='E2-HU3'!F11 -> 0 | K11: =IF(AND(E11>=2,F11>=1),"Sí cumple","NO cumple") -> Sí cumple
A12: E2-HU4 | B12: Consultar rutina asignada | C12: Sprint 2 | D12: ='E2-HU4'!F5 -> 6 | E12: ='E2-HU4'!F12 -> 4 | F12: ='E2-HU4'!F13 -> 2 | G12: ='E2-HU4'!F6 -> 6 | H12: ='E2-HU4'!F7 -> 6 | I12: ='E2-HU4'!F8 -> 0 | J12: ='E2-HU4'!F11 -> 0 | K12: =IF(AND(E12>=2,F12>=1),"Sí cumple","NO cumple") -> Sí cumple
A13: TOTAL | D13: =SUM(D5:D12) -> 68 | E13: =SUM(E5:E12) -> 27 | F13: =SUM(F5:F12) -> 41 | G13: =SUM(G5:G12) -> 68 | H13: =SUM(H5:H12) -> 68 | I13: =SUM(I5:I12) -> 0 | J13: =SUM(J5:J12) -> 0
A15: Nota: Sprint 1 = E1 (usuarios) y Sprint 2 = E2 (rutinas), según el orden del alcance del proyecto. Si la profe cuenta los sprints distinto, solo cambia la columna Sprint.

Sheet E1-HU1
A1: DISEÑO DE CASOS DE PRUEBA (CP) — SAIYAGYM · E1-HU1 Registrar usuarios
A2: Rol que ejecuta: Administrador. Celdas amarillas = para completar al ejecutar. Alcance y estadísticas se calculan solos.
A4: GENERALIDADES DE LA PRUEBA | E4: ESTADÍSTICAS
A5: Fecha | B5: 2026-10-20 | E5: Total CP diseñados | F5: =COUNTA(A19:A114) -> 16
A6: HU | B6: E1-HU1 — Registrar usuarios | E6: Total CP ejecutados (OK + NOK) | F6: =COUNTIF(F19:F114,"OK")+COUNTIF(F19:F114,"NOK") -> 16
A7: Módulo | B7: Gestión de usuarios (Sprint 1) | E7: CP con resultado OK | F7: =COUNTIF(F19:F114,"OK") -> 16
A8: No. SP | E8: CP con resultado NOK | F8: =COUNTIF(F19:F114,"NOK") -> 0
A9: Iteración | E9: % OK sobre ejecutados | F9: =IF(F6=0,0,F7/F6) -> 1
A10: Tipo de prueba | B10: Funcional | E10: % NOK sobre ejecutados | F10: =IF(F6=0,0,F8/F6) -> 0
A11: Alcance (CP por criterio de aceptación) | E11: CP pendientes de ejecutar | F11: =F5-F6 -> 0
A12: CA1 · Registro exitoso | B12: =COUNTIF(A19:A114,"*_CA1_*") -> 4 | E12: CP positivos (+) | F12: =COUNTIF(D19:D114,"Positivo*") -> 4
A13: CA2 · Campos obligatorios incompletos | B13: =COUNTIF(A19:A114,"*_CA2_*") -> 9 | E13: CP negativos (-) | F13: =COUNTIF(D19:D114,"Negativo*") -> 12
A14: CA3 · Usuario duplicado | B14: =COUNTIF(A19:A114,"*_CA3_*") -> 3 | E14: Errores de nivel Baja | F14: =COUNTIF(H19:H114,"Baja") -> 0
A15: CA4 | B15: =COUNTIF(A19:A114,"*_CA4_*") -> 0 | E15: Errores de nivel Media | F15: =COUNTIF(H19:H114,"Media") -> 0
A16: Total CP | B16: =SUM(B12:B15) -> 16 | E16: Errores de nivel Alta | F16: =COUNTIF(H19:H114,"Alta") -> 0
A17: DETALLE (CP)
A18: ID_CP | B18: Campos | C18: Valores | D18: Sentido (+/-) | E18: Resultado esperado | F18: Resultado real (OK / NOK) | G18: Evidencia (enlace) o descripción del fallo | H18: Tipo / Nivel del error | I18: Observación
A19: HE1_HU1_CA1_CP001 | B19: Nombre completo | C19: Pedro Ruiz | D19: Positivo (+) | E19: Entonces CA1: el sistema crea el usuario y muestra «Usuario registrado correctamente.» | F19: OK | G19: https://docs.google.com/document/d/1QQVp4MpEKhB28qrx3a3Iag5cRzZDnUSb/edit?usp=drive_link&ouid=103533695958335943637&rtpof=true&sd=true | I19: Precondición: sesión de administrador, pantalla Usuarios. Caso base. Queda registrado el documento 55550001 (lo usan otros CP).
B20: Número de documento | C20: 55550001
B21: Teléfono | C21: 3101234567
B22: Correo electrónico | C22: pedro@mail.com
B23: Rol | C23: usuario
B24: Contraseña | C24: Clave12345
A25: HE1_HU1_CA1_CP002 | B25: Nombre completo | C25: Laura Mora | D25: Positivo (+) | E25: Entonces CA1: el sistema crea el usuario y muestra «Usuario registrado correctamente.» | F25: OK | G25: https://docs.google.com/document/d/1QQVp4MpEKhB28qrx3a3Iag5cRzZDnUSb/edit?usp=drive_link&ouid=103533695958335943637&rtpof=true&sd=true | I25: Precondición: sesión de administrador, pantalla Usuarios. Rol entrenador y teléfono con indicativo.
B26: Número de documento | C26: 55550002
B27: Teléfono | C27: +57 310 555 0002
B28: Correo electrónico | C28: laura@mail.com
B29: Rol | C29: entrenador
B30: Contraseña | C30: Entren2026
A31: HE1_HU1_CA1_CP003 | B31: Nombre completo | C31: Ana Torres | D31: Positivo (+) | E31: Entonces CA1: el sistema crea el usuario y muestra «Usuario registrado correctamente.» | F31: OK | G31: https://docs.google.com/document/d/1QQVp4MpEKhB28qrx3a3Iag5cRzZDnUSb/edit?usp=drive_link&ouid=103533695958335943637&rtpof=true&sd=true | I31: Precondición: sesión de administrador, pantalla Usuarios. Rol administrador y documento con letras.
B32: Número de documento | C32: AB1234
B33: Teléfono | C33: 3205550003
B34: Correo electrónico | C34: ana.torres@mail.com
B35: Rol | C35: administrador
B36: Contraseña | C36: Admin2026
A37: HE1_HU1_CA1_CP004 | B37: Nombre completo | C37: Luis Gómez | D37: Positivo (+) | E37: Entonces CA1: el sistema crea el usuario y muestra «Usuario registrado correctamente.» | F37: OK | G37: https://docs.google.com/document/d/1QQVp4MpEKhB28qrx3a3Iag5cRzZDnUSb/edit?usp=drive_link&ouid=103533695958335943637&rtpof=true&sd=true | I37: Precondición: sesión de administrador, pantalla Usuarios. Valores límite: documento de 4 caracteres y contraseña de 8. Queda guardado como A123 (rol usuario, sin rutina: sirve para E2-HU4).
B38: Número de documento | C38: A123
B39: Teléfono | C39: 3005550004
B40: Correo electrónico | C40: luis@mail.com
B41: Rol | C41: usuario
...

Sheet E1-HU2
A1: DISEÑO DE CASOS DE PRUEBA (CP) — SAIYAGYM · E1-HU2 Actualizar información de usuarios
A2: Rol que ejecuta: Administrador. Celdas amarillas = para completar al ejecutar. Alcance y estadísticas se calculan solos.
A4: GENERALIDADES DE LA PRUEBA | E4: ESTADÍSTICAS
A5: Fecha | B5: 2026-10-20 | E5: Total CP diseñados | F5: =COUNTA(A19:A72) -> 9
A6: HU | B6: E1-HU2 — Actualizar información de usuarios | E6: Total CP ejecutados (OK + NOK) | F6: =COUNTIF(F19:F72,"OK")+COUNTIF(F19:F72,"NOK") -> 9
A7: Módulo | B7: Gestión de usuarios (Sprint 1) | E7: CP con resultado OK | F7: =COUNTIF(F19:F72,"OK") -> 9
A8: No. SP | E8: CP con resultado NOK | F8: =COUNTIF(F19:F72,"NOK") -> 0
A9: Iteración | E9: % OK sobre ejecutados | F9: =IF(F6=0,0,F7/F6) -> 1
A10: Tipo de prueba | B10: Funcional | E10: % NOK sobre ejecutados | F10: =IF(F6=0,0,F8/F6) -> 0
A11: Alcance (CP por criterio de aceptación) | E11: CP pendientes de ejecutar | F11: =F5-F6 -> 0
A12: CA1 · Actualización exitosa | B12: =COUNTIF(A19:A72,"*_CA1_*") -> 3 | E12: CP positivos (+) | F12: =COUNTIF(D19:D72,"Positivo*") -> 3
A13: CA2 · Usuario no encontrado | B13: =COUNTIF(A19:A72,"*_CA2_*") -> 1 | E13: CP negativos (-) | F13: =COUNTIF(D19:D72,"Negativo*") -> 6
A14: CA3 · Datos incompletos | B14: =COUNTIF(A19:A72,"*_CA3_*") -> 5 | E14: Errores de nivel Baja | F14: =COUNTIF(H19:H72,"Baja") -> 0
A15: CA4 | B15: =COUNTIF(A19:A72,"*_CA4_*") -> 0 | E15: Errores de nivel Media | F15: =COUNTIF(H19:H72,"Media") -> 0
A16: Total CP | B16: =SUM(B12:B15) -> 9 | E16: Errores de nivel Alta | F16: =COUNTIF(H19:H72,"Alta") -> 0
A17: DETALLE (CP)
A18: ID_CP | B18: Campos | C18: Valores | D18: Sentido (+/-) | E18: Resultado esperado | F18: Resultado real (OK / NOK) | G18: Evidencia (enlace) o descripción del fallo | H18: Tipo / Nivel del error | I18: Observación
A19: HE1_HU2_CA1_CP001 | B19: Nombre completo | C19: Pedro Ruiz | D19: Positivo (+) | E19: Entonces CA1: el sistema guarda los cambios y muestra «Usuario actualizado correctamente.» | F19: OK | G19: https://docs.google.com/document/d/1qH6x9oWqjPh-aAiX5MJjBOjreEm26viX/edit?usp=drive_link&ouid=103533695958335943637&rtpof=true&sd=true | I19: Precondición: sesión de administrador; clic en «Editar» del usuario. Usuario: Pedro Ruiz (E1-HU1 CA1_CP001). Solo cambia el teléfono; la lista debe mostrar el nuevo valor.
B20: Número de documento | C20: 55550001
B21: Teléfono | C21: 3109998877
B22: Correo electrónico | C22: pedro@mail.com
B23: Rol | C23: usuario
B24: Contraseña | C24: (vacío = conserva la actual)
A25: HE1_HU2_CA1_CP002 | B25: Nombre completo | C25: Laura Mora Díaz | D25: Positivo (+) | E25: Entonces CA1: el sistema guarda los cambios y muestra «Usuario actualizado correctamente.» | F25: OK | G25: https://docs.google.com/document/d/1qH6x9oWqjPh-aAiX5MJjBOjreEm26viX/edit?usp=drive_link&ouid=103533695958335943637&rtpof=true&sd=true | I25: Precondición: sesión de administrador; clic en «Editar» del usuario. Usuario: Laura Mora (E1-HU1 CA1_CP002). Cambia nombre y correo.
B26: Número de documento | C26: 55550002
B27: Teléfono | C27: +57 310 555 0002
B28: Correo electrónico | C28: laura.mora@mail.com
B29: Rol | C29: entrenador
B30: Contraseña | C30: (vacío = conserva la actual)
A31: HE1_HU2_CA1_CP003 | B31: Nombre completo | C31: Pedro Ruiz | D31: Positivo (+) | E31: Entonces CA1: el sistema guarda los cambios y muestra «Usuario actualizado correctamente.» | F31: OK | G31: https://docs.google.com/document/d/1qH6x9oWqjPh-aAiX5MJjBOjreEm26viX/edit?usp=drive_link&ouid=103533695958335943637&rtpof=true&sd=true | I31: Precondición: sesión de administrador; clic en «Editar» del usuario. Cambio de contraseña: después Pedro debe poder iniciar sesión con Nueva2026.
B32: Número de documento | C32: 55550001
B33: Teléfono | C33: 3109998877
B34: Correo electrónico | C34: pedro@mail.com
B35: Rol | C35: usuario
B36: Contraseña | C36: Nueva2026
A37: HE1_HU2_CA2_CP001 | B37: Nombre completo | C37: Temporal Prueba | D37: Negativo (-) | E37: Entonces CA2: el sistema rechaza los cambios y muestra «El usuario no existe.»; el formulario se limpia y la lista se actualiza. | F37: OK | G37: https://docs.google.com/document/d/1qH6x9oWqjPh-aAiX5MJjBOjreEm26viX/edit?usp=drive_link&ouid=103533695958335943637&rtpof=true&sd=true | I37: Precondición: sesión de administrador; clic en «Editar» del usuario. Usuario temporal 55559999: se registra, se pulsa «Editar» y, sin cerrar el formulario, se borra de la base de datos con SQL. Luego se cambia el teléfono y se pulsa «Guardar cambios» (pasos en el documento Pasos_E1-HU2).
B38: Número de documento | C38: 55559999
B39: Teléfono | C39: 3109998877
B40: Correo electrónico | C40: temporal@mail.com
B41: Rol | C41: usuario
...

Sheet E1-HU3
A1: DISEÑO DE CASOS DE PRUEBA (CP) — SAIYAGYM · E1-HU3 Consultar información de usuarios
A2: Rol que ejecuta: Administrador. Celdas amarillas = para completar al ejecutar. Alcance y estadísticas se calculan solos.
A4: GENERALIDADES DE LA PRUEBA | E4: ESTADÍSTICAS
A5: Fecha | B5: 2026-10-20 | E5: Total CP diseñados | F5: =COUNTA(A19:A32) -> 7
A6: HU | B6: E1-HU3 — Consultar información de usuarios | E6: Total CP ejecutados (OK + NOK) | F6: =COUNTIF(F19:F32,"OK")+COUNTIF(F19:F32,"NOK") -> 7
A7: Módulo | B7: Gestión de usuarios (Sprint 1) | E7: CP con resultado OK | F7: =COUNTIF(F19:F32,"OK") -> 7
A8: No. SP | E8: CP con resultado NOK | F8: =COUNTIF(F19:F32,"NOK") -> 0
A9: Iteración | E9: % OK sobre ejecutados | F9: =IF(F6=0,0,F7/F6) -> 1
A10: Tipo de prueba | B10: Funcional | E10: % NOK sobre ejecutados | F10: =IF(F6=0,0,F8/F6) -> 0
A11: Alcance (CP por criterio de aceptación) | E11: CP pendientes de ejecutar | F11: =F5-F6 -> 0
A12: CA1 · Usuario encontrado | B12: =COUNTIF(A19:A32,"*_CA1_*") -> 3 | E12: CP positivos (+) | F12: =COUNTIF(D19:D32,"Positivo*") -> 3
A13: CA2 · Usuario no encontrado | B13: =COUNTIF(A19:A32,"*_CA2_*") -> 2 | E13: CP negativos (-) | F13: =COUNTIF(D19:D32,"Negativo*") -> 4
A14: CA3 · Criterio de búsqueda vacío | B14: =COUNTIF(A19:A32,"*_CA3_*") -> 2 | E14: Errores de nivel Baja | F14: =COUNTIF(H19:H32,"Baja") -> 0
A15: CA4 | B15: =COUNTIF(A19:A32,"*_CA4_*") -> 0 | E15: Errores de nivel Media | F15: =COUNTIF(H19:H32,"Media") -> 0
A16: Total CP | B16: =SUM(B12:B15) -> 7 | E16: Errores de nivel Alta | F16: =COUNTIF(H19:H32,"Alta") -> 0
A17: DETALLE (CP)
A18: ID_CP | B18: Campos | C18: Valores | D18: Sentido (+/-) | E18: Resultado esperado | F18: Resultado real (OK / NOK) | G18: Evidencia (enlace) o descripción del fallo | H18: Tipo / Nivel del error | I18: Observación
A19: HE1_HU3_CA1_CP001 | B19: Campo de búsqueda | C19: 10000003 | D19: Positivo (+) | E19: Entonces CA1: el sistema muestra solo a Camila Pérez con sus datos (documento, teléfono, correo, rol, estado). | F19: OK | G19: https://docs.google.com/document/d/1_C8d_ZDSL8BJSZhFncwF0chnvJCmjNM0/edit?usp=drive_link&ouid=103533695958335943637&rtpof=true&sd=true | I19: Precondición: sesión de administrador, lista «Usuarios registrados». Se usan los usuarios de demostración (db:seed). Búsqueda por documento.
B20: Acción | C20: Clic en «Buscar»
A21: HE1_HU3_CA1_CP002 | B21: Campo de búsqueda | C21: camila | D21: Positivo (+) | E21: Entonces CA1: el sistema muestra a Camila Pérez (la búsqueda no distingue mayúsculas). | F21: OK | G21: https://docs.google.com/document/d/1_C8d_ZDSL8BJSZhFncwF0chnvJCmjNM0/edit?usp=drive_link&ouid=103533695958335943637&rtpof=true&sd=true | I21: Precondición: sesión de administrador, lista «Usuarios registrados». Se usan los usuarios de demostración (db:seed). Búsqueda por nombre parcial en minúscula.
B22: Acción | C22: Clic en «Buscar»
A23: HE1_HU3_CA1_CP003 | B23: Campo de búsqueda | C23: gómez | D23: Positivo (+) | E23: Entonces CA1: el sistema muestra a Andrés Gómez con estado Inactivo. | F23: OK | G23: https://docs.google.com/document/d/1_C8d_ZDSL8BJSZhFncwF0chnvJCmjNM0/edit?usp=drive_link&ouid=103533695958335943637&rtpof=true&sd=true | I23: Precondición: sesión de administrador, lista «Usuarios registrados». Se usan los usuarios de demostración (db:seed). Búsqueda por apellido: aparecen también otros usuarios cuyo nombre contenga «gómez» (por ejemplo Luis Gómez si ya se registró).
B24: Acción | C24: Clic en «Buscar»
A25: HE1_HU3_CA2_CP001 | B25: Campo de búsqueda | C25: zzz999 | D25: Negativo (-) | E25: Entonces CA2: la lista queda vacía y muestra el recuadro «No encontramos coincidencias» con el texto «No se encontró ningún usuario con ese nombre o documento.» | F25: OK | G25: https://docs.google.com/document/d/1_C8d_ZDSL8BJSZhFncwF0chnvJCmjNM0/edit?usp=drive_link&ouid=103533695958335943637&rtpof=true&sd=true | I25: Precondición: sesión de administrador, lista «Usuarios registrados». Se usan los usuarios de demostración (db:seed). Texto que no existe.
B26: Acción | C26: Clic en «Buscar»
A27: HE1_HU3_CA2_CP002 | B27: Campo de búsqueda | C27: 99999999 | D27: Negativo (-) | E27: Entonces CA2: la lista queda vacía y muestra el recuadro «No encontramos coincidencias» con el texto «No se encontró ningún usuario con ese nombre o documento.» | F27: OK | G27: https://docs.google.com/document/d/1_C8d_ZDSL8BJSZhFncwF0chnvJCmjNM0/edit?usp=drive_link&ouid=103533695958335943637&rtpof=true&sd=true | I27: Precondición: sesión de administrador, lista «Usuarios registrados». Se usan los usuarios de demostración (db:seed). Documento que no existe.
B28: Acción | C28: Clic en «Buscar»
A29: HE1_HU3_CA3_CP001 | B29: Campo de búsqueda | C29: (vacío) | D29: Negativo (-) | E29: Entonces CA3: el sistema muestra «Ingresa un nombre o número de documento para buscar.» | F29: OK | G29: https://docs.google.com/document/d/1_C8d_ZDSL8BJSZhFncwF0chnvJCmjNM0/edit?usp=drive_link&ouid=103533695958335943637&rtpof=true&sd=true | I29: Precondición: sesión de administrador, lista «Usuarios registrados». Se usan los usuarios de demostración (db:seed). Campo vacío.
B30: Acción | C30: Clic en «Buscar»
A31: HE1_HU3_CA3_CP002 | B31: Campo de búsqueda | C31: (solo espacios) | D31: Negativo (-) | E31: Entonces CA3: el sistema muestra «Ingresa un nombre o número de documento para buscar.» | F31: OK | G31: https://docs.google.com/document/d/1_C8d_ZDSL8BJSZhFncwF0chnvJCmjNM0/edit?usp=drive_link&ouid=103533695958335943637&rtpof=true&sd=true | I31: Precondición: sesión de administrador, lista «Usuarios registrados». Se usan los usuarios de demostración (db:seed). Solo espacios: se trata como vacío.
B32: Acción | C32: Clic en «Buscar»

Sheet E1-HU4
A1: DISEÑO DE CASOS DE PRUEBA (CP) — SAIYAGYM · E1-HU4 Gestionar estado de usuarios
A2: Rol que ejecuta: Administrador. Celdas amarillas = para completar al ejecutar. Alcance y estadísticas se calculan solos.
A4: GENERALIDADES DE LA PRUEBA | E4: ESTADÍSTICAS
A5: Fecha | B5: 2026-10-20 | E5: Total CP diseñados | F5: =COUNTA(A19:A36) -> 6
A6: HU | B6: E1-HU4 — Gestionar estado de usuarios | E6: Total CP ejecutados (OK + NOK) | F6: =COUNTIF(F19:F36,"OK")+COUNTIF(F19:F36,"NOK") -> 6
A7: Módulo | B7: Gestión de usuarios (Sprint 1) | E7: CP con resultado OK | F7: =COUNTIF(F19:F36,"OK") -> 6
A8: No. SP | E8: CP con resultado NOK | F8: =COUNTIF(F19:F36,"NOK") -> 0
A9: Iteración | E9: % OK sobre ejecutados | F9: =IF(F6=0,0,F7/F6) -> 1
A10: Tipo de prueba | B10: Funcional | E10: % NOK sobre ejecutados | F10: =IF(F6=0,0,F8/F6) -> 0
A11: Alcance (CP por criterio de aceptación) | E11: CP pendientes de ejecutar | F11: =F5-F6 -> 0
A12: CA1 · Activar usuario | B12: =COUNTIF(A19:A36,"*_CA1_*") -> 2 | E12: CP positivos (+) | F12: =COUNTIF(D19:D36,"Positivo*") -> 4
A13: CA2 · Inactivar usuario | B13: =COUNTIF(A19:A36,"*_CA2_*") -> 2 | E13: CP negativos (-) | F13: =COUNTIF(D19:D36,"Negativo*") -> 2
A14: CA3 · Usuario no encontrado | B14: =COUNTIF(A19:A36,"*_CA3_*") -> 2 | E14: Errores de nivel Baja | F14: =COUNTIF(H19:H36,"Baja") -> 0
A15: CA4 | B15: =COUNTIF(A19:A36,"*_CA4_*") -> 0 | E15: Errores de nivel Media | F15: =COUNTIF(H19:H36,"Media") -> 0
A16: Total CP | B16: =SUM(B12:B15) -> 6 | E16: Errores de nivel Alta | F16: =COUNTIF(H19:H36,"Alta") -> 0
A17: DETALLE (CP)
A18: ID_CP | B18: Campos | C18: Valores | D18: Sentido (+/-) | E18: Resultado esperado | F18: Resultado real (OK / NOK) | G18: Evidencia (enlace) o descripción del fallo | H18: Tipo / Nivel del error | I18: Observación
A19: HE1_HU4_CA1_CP001 | B19: Usuario | C19: Andrés Gómez (10000004) | D19: Positivo (+) | E19: Entonces CA1: el sistema cambia el estado a Activo y muestra «Andrés Gómez fue activado correctamente.» | F19: OK | G19: https://docs.google.com/document/d/1-qbGi9E85ciCa6cZzggyylpTzn9xzpVn/edit?usp=drive_link&ouid=103533695958335943637&rtpof=true&sd=true | I19: Precondición: sesión de administrador, lista «Usuarios registrados». Usuario inactivo de demostración (db:seed).
B20: Estado actual | C20: Inactivo
B21: Acción | C21: Clic en «Activar»
A22: HE1_HU4_CA1_CP002 | B22: Usuario | C22: Pedro Ruiz (55550001) | D22: Positivo (+) | E22: Entonces CA1: el sistema cambia el estado a Activo y muestra «Pedro Ruiz fue activado correctamente.» | F22: OK | G22: https://docs.google.com/document/d/1-qbGi9E85ciCa6cZzggyylpTzn9xzpVn/edit?usp=drive_link&ouid=103533695958335943637&rtpof=true&sd=true | I22: Precondición: sesión de administrador, lista «Usuarios registrados». Precondición extra: Pedro ya fue inactivado en CA2_CP001.
B23: Estado actual | C23: Inactivo
B24: Acción | C24: Clic en «Activar»
A25: HE1_HU4_CA2_CP001 | B25: Usuario | C25: Pedro Ruiz (55550001) | D25: Positivo (+) | E25: Entonces CA2: el sistema cambia el estado a Inactivo y muestra «Pedro Ruiz fue inactivado correctamente.» | F25: OK | G25: https://docs.google.com/document/d/1-qbGi9E85ciCa6cZzggyylpTzn9xzpVn/edit?usp=drive_link&ouid=103533695958335943637&rtpof=true&sd=true | I25: Precondición: sesión de administrador, lista «Usuarios registrados». El registro NO se elimina: solo cambia el estado.
B26: Estado actual | C26: Activo
B27: Acción | C27: Clic en «Inactivar»
A28: HE1_HU4_CA2_CP002 | B28: Usuario | C28: Laura Mora Díaz (55550002) | D28: Positivo (+) | E28: Entonces CA2: el sistema cambia el estado a Inactivo y muestra «Laura Mora Díaz fue inactivado correctamente.» | F28: OK | G28: https://docs.google.com/document/d/1-qbGi9E85ciCa6cZzggyylpTzn9xzpVn/edit?usp=drive_link&ouid=103533695958335943637&rtpof=true&sd=true | I28: Precondición: sesión de administrador, lista «Usuarios registrados». Después se vuelve a activar para no afectar otras pruebas.
B29: Estado actual | C29: Activo
B30: Acción | C30: Clic en «Inactivar»
A31: HE1_HU4_CA3_CP001 | B31: Usuario | C31: Temporal 2 (55559998) | D31: Negativo (-) | E31: Entonces CA3: el sistema rechaza el cambio y muestra «El usuario no existe.» | F31: OK | G31: https://docs.google.com/document/d/1-qbGi9E85ciCa6cZzggyylpTzn9xzpVn/edit?usp=drive_link&ouid=103533695958335943637&rtpof=true&sd=true | I31: Precondición: sesión de administrador, lista «Usuarios registrados». Usuario temporal 55559998: se registra, y con la fila visible se borra de la base de datos con SQL; luego se pulsa «Inactivar» (pasos en el documento Pasos_E1-HU4).
B32: Estado actual | C32: Activo (la fila sigue en pantalla pero ya se borró de la base de datos)
B33: Acción | C33: Clic en «Inactivar»
A34: HE1_HU4_CA3_CP002 | B34: Usuario | C34: Administrador Demo (10000001): la fila del propio administrador | D34: Negativo (-) | E34: Entonces CA3: el botón «Inactivar» de esa fila aparece deshabilitado y al pasar el cursor muestra «No puedes cambiar el estado de tu propio usuario»; no se puede inactivar. | F34: OK | G34: https://docs.google.com/document/d/1-qbGi9E85ciCa6cZzggyylpTzn9xzpVn/edit?usp=drive_link&ouid=103533695958335943637&rtpof=true&sd=true | I34: Precondición: sesión de administrador, lista «Usuarios registrados». CP adicional: el administrador no puede inactivarse a sí mismo (el sistema lo impide desde la pantalla).
B35: Estado actual | C35: Activo
B36: Acción | C36: Intentar pulsar «Inactivar»

Sheet E2-HU1
A1: DISEÑO DE CASOS DE PRUEBA (CP) — SAIYAGYM · E2-HU1 Crear rutina de entrenamiento
A2: Rol que ejecuta: Entrenador. Celdas amarillas = para completar al ejecutar. Alcance y estadísticas se calculan solos.
A4: GENERALIDADES DE LA PRUEBA | E4: ESTADÍSTICAS
A5: Fecha | B5: 2026-10-20 | E5: Total CP diseñados | F5: =COUNTA(A19:A47) -> 10
A6: HU | B6: E2-HU1 — Crear rutina de entrenamiento | E6: Total CP ejecutados (OK + NOK) | F6: =COUNTIF(F19:F47,"OK")+COUNTIF(F19:F47,"NOK") -> 10
A7: Módulo | B7: Gestión de rutinas (Sprint 2) | E7: CP con resultado OK | F7: =COUNTIF(F19:F47,"OK") -> 10
A8: No. SP | E8: CP con resultado NOK | F8: =COUNTIF(F19:F47,"NOK") -> 0
A9: Iteración | E9: % OK sobre ejecutados | F9: =IF(F6=0,0,F7/F6) -> 1
A10: Tipo de prueba | B10: Funcional | E10: % NOK sobre ejecutados | F10: =IF(F6=0,0,F8/F6) -> 0
A11: Alcance (CP por criterio de aceptación) | E11: CP pendientes de ejecutar | F11: =F5-F6 -> 0
A12: CA1 · Creación exitosa | B12: =COUNTIF(A19:A47,"*_CA1_*") -> 3 | E12: CP positivos (+) | F12: =COUNTIF(D19:D47,"Positivo*") -> 3
A13: CA2 · Datos incompletos | B13: =COUNTIF(A19:A47,"*_CA2_*") -> 5 | E13: CP negativos (-) | F13: =COUNTIF(D19:D47,"Negativo*") -> 7
A14: CA3 · Ejercicio no seleccionado | B14: =COUNTIF(A19:A47,"*_CA3_*") -> 2 | E14: Errores de nivel Baja | F14: =COUNTIF(H19:H47,"Baja") -> 0
A15: CA4 | B15: =COUNTIF(A19:A47,"*_CA4_*") -> 0 | E15: Errores de nivel Media | F15: =COUNTIF(H19:H47,"Media") -> 0
A16: Total CP | B16: =SUM(B12:B15) -> 10 | E16: Errores de nivel Alta | F16: =COUNTIF(H19:H47,"Alta") -> 0
A17: DETALLE (CP)
A18: ID_CP | B18: Campos | C18: Valores | D18: Sentido (+/-) | E18: Resultado esperado | F18: Resultado real (OK / NOK) | G18: Evidencia (enlace) o descripción del fallo | H18: Tipo / Nivel del error | I18: Observación
A19: HE2_HU1_CA1_CP001 | B19: Nombre de la rutina | C19: Fuerza tren superior | D19: Positivo (+) | E19: Entonces CA1: el sistema crea la rutina y muestra «Rutina registrada correctamente.» | F19: OK | G19: https://docs.google.com/document/d/1NfQHTG3vGCu2g09koHiX7udgol7BF719/edit?usp=drive_link&ouid=103533695958335943637&rtpof=true&sd=true | I19: Precondición: sesión de entrenador (10000002), pantalla Rutinas, formulario «Nueva rutina». Rutina de 2 ejercicios. Se usa luego en E2-HU2 y E2-HU4.
B20: Objetivo | C20: Ganar fuerza y masa muscular
B21: Ejercicio 1 | C21: Press banca · 4 series x 10 rep.
B22: Ejercicio 2 | C22: Remo con barra · 4 series x 10 rep.
A23: HE2_HU1_CA1_CP002 | B23: Nombre de la rutina | C23: Cardio básico | D23: Positivo (+) | E23: Entonces CA1: el sistema crea la rutina y muestra «Rutina registrada correctamente.» | F23: OK | G23: https://docs.google.com/document/d/1NfQHTG3vGCu2g09koHiX7udgol7BF719/edit?usp=drive_link&ouid=103533695958335943637&rtpof=true&sd=true | I23: Precondición: sesión de entrenador (10000002), pantalla Rutinas, formulario «Nueva rutina». Rutina con un solo ejercicio (mínimo permitido).
B24: Objetivo | C24: Mejorar resistencia
B25: Ejercicio 1 | C25: Sentadilla libre · 3 series x 15 rep.
A26: HE2_HU1_CA1_CP003 | B26: Nombre de la rutina | C26: Pierna intensiva | D26: Positivo (+) | E26: Entonces CA1: el sistema crea la rutina y muestra «Rutina registrada correctamente.» | F26: OK | G26: https://docs.google.com/document/d/1NfQHTG3vGCu2g09koHiX7udgol7BF719/edit?usp=drive_link&ouid=103533695958335943637&rtpof=true&sd=true | I26: Precondición: sesión de entrenador (10000002), pantalla Rutinas, formulario «Nueva rutina». Valores límite: 20 series y 200 repeticiones (máximos permitidos).
B27: Objetivo | C27: Aumentar resistencia muscular
B28: Ejercicio 1 | C28: Prensa de piernas · 20 series x 200 rep.
A29: HE2_HU1_CA2_CP001 | B29: Nombre de la rutina | C29: (vacío) | D29: Negativo (-) | E29: Entonces CA2: el sistema rechaza el registro y muestra «Faltan datos obligatorios de la rutina: Nombre de la rutina.» | F29: OK | G29: https://docs.google.com/document/d/1NfQHTG3vGCu2g09koHiX7udgol7BF719/edit?usp=drive_link&ouid=103533695958335943637&rtpof=true&sd=true | I29: Precondición: sesión de entrenador (10000002), pantalla Rutinas, formulario «Nueva rutina». Nombre vacío.
B30: Objetivo | C30: Ganar fuerza
B31: Ejercicio 1 | C31: Press banca · 4 series x 10 rep.
A32: HE2_HU1_CA2_CP002 | B32: Nombre de la rutina | C32: Fuerza tren superior | D32: Negativo (-) | E32: Entonces CA2: el sistema rechaza el registro y muestra «Faltan datos obligatorios de la rutina: Objetivo.» | F32: OK | G32: https://docs.google.com/document/d/1NfQHTG3vGCu2g09koHiX7udgol7BF719/edit?usp=drive_link&ouid=103533695958335943637&rtpof=true&sd=true | I32: Precondición: sesión de entrenador (10000002), pantalla Rutinas, formulario «Nueva rutina». Objetivo vacío.
B33: Objetivo | C33: (vacío)
B34: Ejercicio 1 | C34: Press banca · 4 series x 10 rep.
A35: HE2_HU1_CA2_CP003 | B35: Nombre de la rutina | C35: (vacío) | D35: Negativo (-) | E35: Entonces CA2: el sistema rechaza el registro y muestra «Faltan datos obligatorios de la rutina: Nombre de la rutina, Objetivo.» | F35: OK | G35: https://docs.google.com/document/d/1NfQHTG3vGCu2g09koHiX7udgol7BF719/edit?usp=drive_link&ouid=103533695958335943637&rtpof=true&sd=true | I35: Precondición: sesión de entrenador (10000002), pantalla Rutinas, formulario «Nueva rutina». Nombre y objetivo vacíos.
B36: Objetivo | C36: (vacío)
B37: Ejercicio 1 | C37: Press banca · 4 series x 10 rep.
A38: HE2_HU1_CA2_CP004 | B38: Nombre de la rutina | C38: Rutina X | D38: Negativo (-) | E38: Entonces CA2: el sistema rechaza el registro y muestra «El ejercicio 1 no es válido: series entre 1 y 20, repeticiones entre 1 y 200 y nombre de máximo 120 caracteres.» | F38: OK | G38: https://docs.google.com/document/d/1NfQHTG3vGCu2g09koHiX7udgol7BF719/edit?usp=drive_link&ouid=103533695958335943637&rtpof=true&sd=true | I38: Precondición: sesión de entrenador (10000002), pantalla Rutinas, formulario «Nueva rutina». CP adicional: 21 series (fuera del límite).
B39: Objetivo | C39: Objetivo X
B40: Ejercicio 1 | C40: Press banca · 21 series x 10 rep.
A41: HE2_HU1_CA2_CP005 | B41: Nombre de la rutina | C41: Rutina X | D41: Negativo (-) | E41: Entonces CA2: el sistema rechaza el registro y muestra «Completa el nombre, las series y las repeticiones del ejercicio 1.» | F41: OK | G41: https://docs.google.com/document/d/1NfQHTG3vGCu2g09koHiX7udgol7BF719/edit?usp=drive_link&ouid=103533695958335943637&rtpof=true&sd=true | I41: Precondición: sesión de entrenador (10000002), pantalla Rutinas, formulario «Nueva rutina». CP adicional: repeticiones vacías.
...

Sheet E2-HU2
A1: DISEÑO DE CASOS DE PRUEBA (CP) — SAIYAGYM · E2-HU2 Asignar rutina a usuario
A2: Rol que ejecuta: Entrenador. Celdas amarillas = para completar al ejecutar. Alcance y estadísticas se calculan solos.
A4: GENERALIDADES DE LA PRUEBA | E4: ESTADÍSTICAS
A5: Fecha | B5: 2026-10-20 | E5: Total CP diseñados | F5: =COUNTA(A19:A39) -> 7
A6: HU | B6: E2-HU2 — Asignar rutina a usuario | E6: Total CP ejecutados (OK + NOK) | F6: =COUNTIF(F19:F39,"OK")+COUNTIF(F19:F39,"NOK") -> 7
A7: Módulo | B7: Gestión de rutinas (Sprint 2) | E7: CP con resultado OK | F7: =COUNTIF(F19:F39,"OK") -> 7
A8: No. SP | E8: CP con resultado NOK | F8: =COUNTIF(F19:F39,"NOK") -> 0
A9: Iteración | E9: % OK sobre ejecutados | F9: =IF(F6=0,0,F7/F6) -> 1
A10: Tipo de prueba | B10: Funcional | E10: % NOK sobre ejecutados | F10: =IF(F6=0,0,F8/F6) -> 0
A11: Alcance (CP por criterio de aceptación) | E11: CP pendientes de ejecutar | F11: =F5-F6 -> 0
A12: CA1 · Asignación exitosa | B12: =COUNTIF(A19:A39,"*_CA1_*") -> 3 | E12: CP positivos (+) | F12: =COUNTIF(D19:D39,"Positivo*") -> 3
A13: CA2 · Usuario no seleccionado | B13: =COUNTIF(A19:A39,"*_CA2_*") -> 1 | E13: CP negativos (-) | F13: =COUNTIF(D19:D39,"Negativo*") -> 4
A14: CA3 · Usuario no disponible | B14: =COUNTIF(A19:A39,"*_CA3_*") -> 1 | E14: Errores de nivel Baja | F14: =COUNTIF(H19:H39,"Baja") -> 0
A15: CA4 · Rutina no seleccionada | B15: =COUNTIF(A19:A39,"*_CA4_*") -> 2 | E15: Errores de nivel Media | F15: =COUNTIF(H19:H39,"Media") -> 0
A16: Total CP | B16: =SUM(B12:B15) -> 7 | E16: Errores de nivel Alta | F16: =COUNTIF(H19:H39,"Alta") -> 0
A17: DETALLE (CP)
A18: ID_CP | B18: Campos | C18: Valores | D18: Sentido (+/-) | E18: Resultado esperado | F18: Resultado real (OK / NOK) | G18: Evidencia (enlace) o descripción del fallo | H18: Tipo / Nivel del error | I18: Observación
A19: HE2_HU2_CA1_CP001 | B19: Usuario | C19: Camila Pérez | D19: Positivo (+) | E19: Entonces CA1: el sistema asigna la rutina y muestra «La rutina "Fuerza tren superior" fue asignada a Camila Pérez correctamente.» | F19: OK | G19: https://docs.google.com/document/d/1lRqV1zrO9mUMZ58Zv8bgMuRSpJwCJOTD/edit?usp=drive_link&ouid=103533695958335943637&rtpof=true&sd=true | I19: Precondición: sesión de entrenador, tarjeta «Asignar rutina a un usuario»; existen las rutinas de E2-HU1.
B20: Rutina | C20: Fuerza tren superior
B21: Acción | C21: Clic en «Asignar»
A22: HE2_HU2_CA1_CP002 | B22: Usuario | C22: Pedro Ruiz | D22: Positivo (+) | E22: Entonces CA1: el sistema asigna la rutina y muestra «La rutina "Cardio básico" fue asignada a Pedro Ruiz correctamente.» | F22: OK | G22: https://docs.google.com/document/d/1lRqV1zrO9mUMZ58Zv8bgMuRSpJwCJOTD/edit?usp=drive_link&ouid=103533695958335943637&rtpof=true&sd=true | I22: Precondición: sesión de entrenador, tarjeta «Asignar rutina a un usuario»; existen las rutinas de E2-HU1. Pedro debe estar Activo (E1-HU4 CA1_CP002).
B23: Rutina | C23: Cardio básico
B24: Acción | C24: Clic en «Asignar»
A25: HE2_HU2_CA1_CP003 | B25: Usuario | C25: Camila Pérez | D25: Positivo (+) | E25: Entonces CA1: el sistema asigna la nueva rutina; la anterior queda como histórico y Camila ve solo «Cardio básico» en Mi rutina. | F25: OK | G25: https://docs.google.com/document/d/1lRqV1zrO9mUMZ58Zv8bgMuRSpJwCJOTD/edit?usp=drive_link&ouid=103533695958335943637&rtpof=true&sd=true | I25: Precondición: sesión de entrenador, tarjeta «Asignar rutina a un usuario»; existen las rutinas de E2-HU1. Reasignación: Camila ya tenía «Fuerza tren superior». Al terminar queda con «Cardio básico».
B26: Rutina | C26: Cardio básico
B27: Acción | C27: Clic en «Asignar»
A28: HE2_HU2_CA2_CP001 | B28: Usuario | C28: Selecciona un usuario | D28: Negativo (-) | E28: Entonces CA2: el sistema rechaza la asignación y muestra «Selecciona un usuario para asignarle la rutina.» | F28: OK | G28: https://docs.google.com/document/d/1lRqV1zrO9mUMZ58Zv8bgMuRSpJwCJOTD/edit?usp=drive_link&ouid=103533695958335943637&rtpof=true&sd=true | I28: Precondición: sesión de entrenador, tarjeta «Asignar rutina a un usuario»; existen las rutinas de E2-HU1. No se elige usuario.
B29: Rutina | C29: Fuerza tren superior
B30: Acción | C30: Clic en «Asignar»
A31: HE2_HU2_CA3_CP001 | B31: Usuario | C31: Andrés Gómez (inactivo) | D31: Negativo (-) | E31: Entonces CA3: el sistema rechaza la asignación y muestra «El usuario seleccionado está inactivo y no está disponible para asignarle una rutina.» | F31: OK | G31: https://docs.google.com/document/d/1lRqV1zrO9mUMZ58Zv8bgMuRSpJwCJOTD/edit?usp=drive_link&ouid=103533695958335943637&rtpof=true&sd=true | I31: Precondición: sesión de entrenador, tarjeta «Asignar rutina a un usuario»; existen las rutinas de E2-HU1. Andrés debe estar Inactivo: ejecutar antes de activarlo en E1-HU4 CA1_CP001, o volver a inactivarlo.
B32: Rutina | C32: Fuerza tren superior
B33: Acción | C33: Clic en «Asignar»
A34: HE2_HU2_CA4_CP001 | B34: Usuario | C34: Camila Pérez | D34: Negativo (-) | E34: Entonces CA4: el sistema rechaza la asignación y muestra «Selecciona una rutina para asignar.» | F34: OK | G34: https://docs.google.com/document/d/1lRqV1zrO9mUMZ58Zv8bgMuRSpJwCJOTD/edit?usp=drive_link&ouid=103533695958335943637&rtpof=true&sd=true | I34: Precondición: sesión de entrenador, tarjeta «Asignar rutina a un usuario»; existen las rutinas de E2-HU1. No se elige rutina.
B35: Rutina | C35: Selecciona una rutina
B36: Acción | C36: Clic en «Asignar»
A37: HE2_HU2_CA4_CP002 | B37: Usuario | C37: Selecciona un usuario | D37: Negativo (-) | E37: Entonces CA4: el sistema rechaza la asignación y muestra el mensaje de usuario no seleccionado (se valida primero el usuario). | F37: OK | G37: https://docs.google.com/document/d/1lRqV1zrO9mUMZ58Zv8bgMuRSpJwCJOTD/edit?usp=drive_link&ouid=103533695958335943637&rtpof=true&sd=true | I37: Precondición: sesión de entrenador, tarjeta «Asignar rutina a un usuario»; existen las rutinas de E2-HU1. CP adicional: ninguno de los dos seleccionado.
B38: Rutina | C38: Selecciona una rutina
B39: Acción | C39: Clic en «Asignar»

Sheet E2-HU3
A1: DISEÑO DE CASOS DE PRUEBA (CP) — SAIYAGYM · E2-HU3 Modificar rutina de entrenamiento
A2: Rol que ejecuta: Entrenador. Celdas amarillas = para completar al ejecutar. Alcance y estadísticas se calculan solos.
A4: GENERALIDADES DE LA PRUEBA | E4: ESTADÍSTICAS
A5: Fecha | B5: 2026-10-20 | E5: Total CP diseñados | F5: =COUNTA(A19:A43) -> 7
A6: HU | B6: E2-HU3 — Modificar rutina de entrenamiento | E6: Total CP ejecutados (OK + NOK) | F6: =COUNTIF(F19:F43,"OK")+COUNTIF(F19:F43,"NOK") -> 7
A7: Módulo | B7: Gestión de rutinas (Sprint 2) | E7: CP con resultado OK | F7: =COUNTIF(F19:F43,"OK") -> 7
A8: No. SP | E8: CP con resultado NOK | F8: =COUNTIF(F19:F43,"NOK") -> 0
A9: Iteración | E9: % OK sobre ejecutados | F9: =IF(F6=0,0,F7/F6) -> 1
A10: Tipo de prueba | B10: Funcional | E10: % NOK sobre ejecutados | F10: =IF(F6=0,0,F8/F6) -> 0
A11: Alcance (CP por criterio de aceptación) | E11: CP pendientes de ejecutar | F11: =F5-F6 -> 0
A12: CA1 · Modificación exitosa | B12: =COUNTIF(A19:A43,"*_CA1_*") -> 3 | E12: CP positivos (+) | F12: =COUNTIF(D19:D43,"Positivo*") -> 3
A13: CA2 · Rutina no encontrada | B13: =COUNTIF(A19:A43,"*_CA2_*") -> 1 | E13: CP negativos (-) | F13: =COUNTIF(D19:D43,"Negativo*") -> 4
A14: CA3 · Datos obligatorios eliminados | B14: =COUNTIF(A19:A43,"*_CA3_*") -> 3 | E14: Errores de nivel Baja | F14: =COUNTIF(H19:H43,"Baja") -> 0
A15: CA4 | B15: =COUNTIF(A19:A43,"*_CA4_*") -> 0 | E15: Errores de nivel Media | F15: =COUNTIF(H19:H43,"Media") -> 0
A16: Total CP | B16: =SUM(B12:B15) -> 7 | E16: Errores de nivel Alta | F16: =COUNTIF(H19:H43,"Alta") -> 0
A17: DETALLE (CP)
A18: ID_CP | B18: Campos | C18: Valores | D18: Sentido (+/-) | E18: Resultado esperado | F18: Resultado real (OK / NOK) | G18: Evidencia (enlace) o descripción del fallo | H18: Tipo / Nivel del error | I18: Observación
A19: HE2_HU3_CA1_CP001 | B19: Nombre de la rutina | C19: Fuerza tren superior - nivel 2 | D19: Positivo (+) | E19: Entonces CA1: el sistema guarda los cambios y muestra «Rutina modificada correctamente.» | F19: OK | G19: https://docs.google.com/document/d/12UGBbx7oETFpF6f8n3GpEMTCk2YpFju2/edit?usp=drive_link&ouid=103533695958335943637&rtpof=true&sd=true | I19: Precondición: sesión de entrenador, lista «Rutinas registradas»; clic en «Editar». Rutina «Fuerza tren superior»: cambia solo el nombre.
B20: Objetivo | C20: Ganar fuerza y masa muscular
B21: Ejercicio 1 | C21: Press banca · 4 series x 10 rep.
B22: Ejercicio 2 | C22: Remo con barra · 4 series x 10 rep.
A23: HE2_HU3_CA1_CP002 | B23: Nombre de la rutina | C23: Fuerza tren superior - nivel 2 | D23: Positivo (+) | E23: Entonces CA1: el sistema guarda los cambios y muestra «Rutina modificada correctamente.» | F23: OK | G23: https://docs.google.com/document/d/12UGBbx7oETFpF6f8n3GpEMTCk2YpFju2/edit?usp=drive_link&ouid=103533695958335943637&rtpof=true&sd=true | I23: Precondición: sesión de entrenador, lista «Rutinas registradas»; clic en «Editar». Se agrega un tercer ejercicio con «+ Agregar ejercicio». Lo usa E2-HU4 CA4.
B24: Objetivo | C24: Ganar fuerza y masa muscular
B25: Ejercicio 1 | C25: Press banca · 4 series x 10 rep.
B26: Ejercicio 2 | C26: Remo con barra · 4 series x 10 rep.
B27: Ejercicio 3 | C27: Fondos en paralelas · 3 series x 12 rep.
A28: HE2_HU3_CA1_CP003 | B28: Nombre de la rutina | C28: Fuerza tren superior - nivel 2 | D28: Positivo (+) | E28: Entonces CA1: el sistema guarda los cambios y muestra «Rutina modificada correctamente.» | F28: OK | G28: https://docs.google.com/document/d/12UGBbx7oETFpF6f8n3GpEMTCk2YpFju2/edit?usp=drive_link&ouid=103533695958335943637&rtpof=true&sd=true | I28: Precondición: sesión de entrenador, lista «Rutinas registradas»; clic en «Editar». Se cambian series y repeticiones del primer ejercicio.
B29: Objetivo | C29: Ganar fuerza y masa muscular
B30: Ejercicio 1 | C30: Press banca · 5 series x 8 rep.
B31: Ejercicio 2 | C31: Remo con barra · 4 series x 10 rep.
B32: Ejercicio 3 | C32: Fondos en paralelas · 3 series x 12 rep.
A33: HE2_HU3_CA2_CP001 | B33: Nombre de la rutina | C33: Rutina temporal | D33: Negativo (-) | E33: Entonces CA2: el sistema rechaza la modificación y muestra «La rutina no fue encontrada.» | F33: OK | G33: https://docs.google.com/document/d/12UGBbx7oETFpF6f8n3GpEMTCk2YpFju2/edit?usp=drive_link&ouid=103533695958335943637&rtpof=true&sd=true | I33: Precondición: sesión de entrenador. Rutina «Rutina temporal»: se crea, se pulsa «Modificar» y, sin cerrar el formulario, se borra de la base de datos con SQL. Luego se pulsa «Guardar cambios» (pasos en el documento Pasos_E2-HU3).
B34: Objetivo | C34: Objetivo temporal
B35: Ejercicio 1 | C35: Press banca · 4 series x 10 rep.
A36: HE2_HU3_CA3_CP001 | B36: Nombre de la rutina | C36: (vacío) | D36: Negativo (-) | E36: Entonces CA3: el sistema rechaza la actualización y muestra «Faltan datos obligatorios de la rutina: Nombre de la rutina.» | F36: OK | G36: https://docs.google.com/document/d/12UGBbx7oETFpF6f8n3GpEMTCk2YpFju2/edit?usp=drive_link&ouid=103533695958335943637&rtpof=true&sd=true | I36: Precondición: sesión de entrenador, lista «Rutinas registradas»; clic en «Editar». Se borra el nombre.
B37: Objetivo | C37: Ganar fuerza y masa muscular
B38: Ejercicio 1 | C38: Press banca · 4 series x 10 rep.
A39: HE2_HU3_CA3_CP002 | B39: Nombre de la rutina | C39: Fuerza tren superior - nivel 2 | D39: Negativo (-) | E39: Entonces CA3: el sistema rechaza la actualización y muestra «Faltan datos obligatorios de la rutina: Objetivo.» | F39: OK | G39: https://docs.google.com/document/d/12UGBbx7oETFpF6f8n3GpEMTCk2YpFju2/edit?usp=drive_link&ouid=103533695958335943637&rtpof=true&sd=true | I39: Precondición: sesión de entrenador, lista «Rutinas registradas»; clic en «Editar». Se borra el objetivo.
B40: Objetivo | C40: (vacío)
B41: Ejercicio 1 | C41: Press banca · 4 series x 10 rep.
...

Sheet E2-HU4
A1: DISEÑO DE CASOS DE PRUEBA (CP) — SAIYAGYM · E2-HU4 Consultar rutina asignada
A2: Rol que ejecuta: Usuario del gimnasio. Celdas amarillas = para completar al ejecutar. Alcance y estadísticas se calculan solos.
A4: GENERALIDADES DE LA PRUEBA | E4: ESTADÍSTICAS
A5: Fecha | B5: 2026-10-20 | E5: Total CP diseñados | F5: =COUNTA(A19:A42) -> 6
A6: HU | B6: E2-HU4 — Consultar rutina asignada | E6: Total CP ejecutados (OK + NOK) | F6: =COUNTIF(F19:F42,"OK")+COUNTIF(F19:F42,"NOK") -> 6
A7: Módulo | B7: Gestión de rutinas (Sprint 2) | E7: CP con resultado OK | F7: =COUNTIF(F19:F42,"OK") -> 6
A8: No. SP | E8: CP con resultado NOK | F8: =COUNTIF(F19:F42,"NOK") -> 0
A9: Iteración | E9: % OK sobre ejecutados | F9: =IF(F6=0,0,F7/F6) -> 1
A10: Tipo de prueba | B10: Funcional | E10: % NOK sobre ejecutados | F10: =IF(F6=0,0,F8/F6) -> 0
A11: Alcance (CP por criterio de aceptación) | E11: CP pendientes de ejecutar | F11: =F5-F6 -> 0
A12: CA1 · Rutina encontrada | B12: =COUNTIF(A19:A42,"*_CA1_*") -> 2 | E12: CP positivos (+) | F12: =COUNTIF(D19:D42,"Positivo*") -> 4
A13: CA2 · Sin rutina asignada | B13: =COUNTIF(A19:A42,"*_CA2_*") -> 1 | E13: CP negativos (-) | F13: =COUNTIF(D19:D42,"Negativo*") -> 2
A14: CA3 · Rutina no disponible | B14: =COUNTIF(A19:A42,"*_CA3_*") -> 1 | E14: Errores de nivel Baja | F14: =COUNTIF(H19:H42,"Baja") -> 0
A15: CA4 · Consulta exitosa | B15: =COUNTIF(A19:A42,"*_CA4_*") -> 2 | E15: Errores de nivel Media | F15: =COUNTIF(H19:H42,"Media") -> 0
A16: Total CP | B16: =SUM(B12:B15) -> 6 | E16: Errores de nivel Alta | F16: =COUNTIF(H19:H42,"Alta") -> 0
A17: DETALLE (CP)
A18: ID_CP | B18: Campos | C18: Valores | D18: Sentido (+/-) | E18: Resultado esperado | F18: Resultado real (OK / NOK) | G18: Evidencia (enlace) o descripción del fallo | H18: Tipo / Nivel del error | I18: Observación
A19: HE2_HU4_CA1_CP001 | B19: Documento (login) | C19: 10000003 | D19: Positivo (+) | E19: Entonces CA1: el sistema muestra «TU RUTINA ACTUAL» con el nombre de la rutina, la fecha de asignación, el objetivo, el entrenador y la tabla de ejercicios. | F19: OK | G19: https://docs.google.com/document/d/1ATvnsXWQaRYnv9AjN803vzqrII0OWsbj/edit?usp=drive_link&ouid=103533695958335943637&rtpof=true&sd=true | I19: Precondición: sesión del usuario, pantalla «Mi rutina». Camila Pérez. Antes, como entrenador, asígnale «Fuerza tren superior - nivel 2» (así se llama esa rutina después de E2-HU3).
B20: Contraseña | C20: Saiya2026
B21: Pantalla | C21: Mi rutina
B22: Situación | C22: Camila con «Fuerza tren superior - nivel 2» asignada
A23: HE2_HU4_CA1_CP002 | B23: Documento (login) | C23: 55550001 | D23: Positivo (+) | E23: Entonces CA1: el sistema muestra «TU RUTINA ACTUAL» con la rutina «Cardio básico» y su ejercicio. | F23: OK | G23: https://docs.google.com/document/d/1ATvnsXWQaRYnv9AjN803vzqrII0OWsbj/edit?usp=drive_link&ouid=103533695958335943637&rtpof=true&sd=true | I23: Precondición: sesión del usuario, pantalla «Mi rutina». Pedro Ruiz (contraseña cambiada en E1-HU2 CA1_CP003), rutina asignada en E2-HU2 CA1_CP002.
B24: Contraseña | C24: Nueva2026
B25: Pantalla | C25: Mi rutina
B26: Situación | C26: Pedro con «Cardio básico» asignada
A27: HE2_HU4_CA2_CP001 | B27: Documento (login) | C27: A123 | D27: Negativo (-) | E27: Entonces CA2: el sistema muestra el aviso «Sin rutina asignada» con el texto «El usuario no tiene una rutina asignada.» | F27: OK | G27: https://docs.google.com/document/d/1ATvnsXWQaRYnv9AjN803vzqrII0OWsbj/edit?usp=drive_link&ouid=103533695958335943637&rtpof=true&sd=true | I27: Precondición: sesión del usuario, pantalla «Mi rutina». Luis Gómez fue registrado en E1-HU1 CA1_CP004 y nunca se le asignó rutina.
B28: Contraseña | C28: Clave123
B29: Pantalla | C29: Mi rutina
B30: Situación | C30: Luis Gómez sin ninguna asignación
A31: HE2_HU4_CA3_CP001 | B31: Documento (login) | C31: 55550001 | D31: Negativo (-) | E31: Entonces CA3: el sistema muestra el aviso «Rutina no disponible» con el texto «La rutina asignada no está disponible.» | F31: OK | G31: https://docs.google.com/document/d/1ATvnsXWQaRYnv9AjN803vzqrII0OWsbj/edit?usp=drive_link&ouid=103533695958335943637&rtpof=true&sd=true | I31: Precondición: sesión del usuario, pantalla «Mi rutina». No hay pantalla para inactivar rutinas: se hace por base de datos (UPDATE rutinas SET estado='Inactiva' WHERE nombre='Cardio básico';) y luego se devuelve a 'Activa'.
B32: Contraseña | C32: Nueva2026
B33: Pantalla | C33: Mi rutina
B34: Situación | C34: Rutina de Pedro marcada como Inactiva
A35: HE2_HU4_CA4_CP001 | B35: Documento (login) | C35: 10000003 | D35: Positivo (+) | E35: Entonces CA4: el sistema muestra la rutina completa: nombre, objetivo, entrenador y los 3 ejercicios con sus series y repeticiones. | F35: OK | G35: https://docs.google.com/document/d/1ATvnsXWQaRYnv9AjN803vzqrII0OWsbj/edit?usp=drive_link&ouid=103533695958335943637&rtpof=true&sd=true | I35: Precondición: sesión del usuario, pantalla «Mi rutina». Rutina vigente correctamente asignada (Camila debe tener «Fuerza tren superior - nivel 2»).
B36: Contraseña | C36: Saiya2026
B37: Pantalla | C37: Mi rutina
B38: Situación | C38: Camila con la rutina de 3 ejercicios (tras E2-HU3 CA1_CP002)
A39: HE2_HU4_CA4_CP002 | B39: Documento (login) | C39: 10000003 | D39: Positivo (+) | E39: Entonces CA4: el sistema muestra solo la rutina vigente («Cardio básico»), no la anterior. | F39: OK | G39: https://docs.google.com/document/d/1ATvnsXWQaRYnv9AjN803vzqrII0OWsbj/edit?usp=drive_link&ouid=103533695958335943637&rtpof=true&sd=true | I39: Precondición: sesión del usuario, pantalla «Mi rutina». Antes, como entrenador, asígnale «Cardio básico» a Camila. Ejecútalo al final de E2-HU4.
B40: Contraseña | C40: Saiya2026
B41: Pantalla | C41: Mi rutina
...

Sheet Formato en blanco
A1: DISEÑO DE CASOS DE PRUEBA (CP) — SAIYAGYM
A2: Plantilla en blanco para las historias de los siguientes sprints. Copia esta hoja (clic derecho > Mover o copiar).
A4: GENERALIDADES DE LA PRUEBA | E4: ESTADÍSTICAS
A5: Fecha | E5: Total CP diseñados | F5: =COUNTA(A19:A58) -> 0
A6: HU | E6: Total CP ejecutados (OK + NOK) | F6: =COUNTIF(F19:F58,"OK")+COUNTIF(F19:F58,"NOK") -> 0
A7: Módulo | E7: CP con resultado OK | F7: =COUNTIF(F19:F58,"OK") -> 0
A8: No. SP | E8: CP con resultado NOK | F8: =COUNTIF(F19:F58,"NOK") -> 0
A9: Iteración | E9: % OK sobre ejecutados | F9: =IF(F6=0,0,F7/F6) -> 0
A10: Tipo de prueba | E10: % NOK sobre ejecutados | F10: =IF(F6=0,0,F8/F6) -> 0
A11: Alcance (CP por criterio de aceptación) | E11: CP pendientes de ejecutar | F11: =F5-F6 -> 0
A12: CA1 | B12: =COUNTIF(A19:A58,"*_CA1_*") -> 0 | E12: CP positivos (+) | F12: =COUNTIF(D19:D58,"Positivo*") -> 0
A13: CA2 | B13: =COUNTIF(A19:A58,"*_CA2_*") -> 0 | E13: CP negativos (-) | F13: =COUNTIF(D19:D58,"Negativo*") -> 0
A14: CA3 | B14: =COUNTIF(A19:A58,"*_CA3_*") -> 0 | E14: Errores de nivel Baja | F14: =COUNTIF(H19:H58,"Baja") -> 0
A15: CA4 | B15: =COUNTIF(A19:A58,"*_CA4_*") -> 0 | E15: Errores de nivel Media | F15: =COUNTIF(H19:H58,"Media") -> 0
A16: Total CP | B16: =SUM(B12:B15) -> 0 | E16: Errores de nivel Alta | F16: =COUNTIF(H19:H58,"Alta") -> 0
A17: DETALLE (CP)
A18: ID_CP | B18: Campos | C18: Valores | D18: Sentido (+/-) | E18: Resultado esperado | F18: Resultado real (OK / NOK) | G18: Evidencia (enlace) o descripción del fallo | H18: Tipo / Nivel del error | I18: Observación
